<?xml version="1.0" ?>
<!-- =================================================================================== -->
<!-- |    This document was autogenerated by xacro from manipulator.xacro              | -->
<!-- |    EDITING THIS FILE BY HAND IS NOT RECOMMENDED                                 | -->
<!-- =================================================================================== -->
<robot name="manipulator">
  <link name="world"/>
  <link name="manipulator/link_0">
    <visual>
      <origin rpy="1.5707963267948966 0 0" xyz="0 0 0"/>
      <geometry>
        <cylinder length="0.3" radius="0.025"/>
      </geometry>
    </visual>
    <collision>
      <origin rpy="1.5707963267948966 0 0" xyz="0 0 0"/>
      <geometry>
        <cylinder length="0.3" radius="0.025"/>
      </geometry>
    </collision>
    <inertial>
      <mass value="0.1"/>
      <origin rpy="0 0 0" xyz="0 0 0"/>
      <inertia ixx="1e-3" ixy="0" ixz="0" iyy="1e-3" iyz="0" izz="1e-3"/>
    </inertial>
  </link>
  <joint name="manipulator/joint_fixed" type="fixed">
    <parent link="world"/>
    <child link="manipulator/link_0"/>
    <origin rpy="0 0 0" xyz="0 0 0.25"/>
  </joint>
  <link name="manipulator/link_1">
    <visual>
      <origin rpy="1.5707963267948966 0 1.5707963267948966" xyz="0 0 0"/>
      <geometry>
        <cylinder length="0.3" radius="0.025"/>
      </geometry>
    </visual>
    <collision>
      <origin rpy="1.5707963267948966 0 1.5707963267948966" xyz="0 0 0"/>
      <geometry>
        <cylinder length="0.3" radius="0.025"/>
      </geometry>
    </collision>
    <inertial>
      <mass value="0.1"/>
      <origin rpy="0 0 0" xyz="0 0 0"/>
      <inertia ixx="1e-3" ixy="0" ixz="0" iyy="1e-3" iyz="0" izz="1e-3"/>
    </inertial>
  </link>
  <joint name="manipulator/joint_0" type="revolute">
    <parent link="manipulator/link_0"/>
    <child link="manipulator/link_1"/>
    <origin rpy="0 0 0" xyz="0. 0. 0."/>
    <axis xyz="0 0 1"/>
    <limit effort="100" lower="-0.78539816339" upper="0.78539816339" velocity="1.0"/>
  </joint>
  <link name="manipulator/finger_0_link_0">
    <visual>
      <origin rpy="0 0 0" xyz="0 0 -0.05"/>
      <geometry>
        <cylinder length="0.1" radius="0.005"/>
      </geometry>
    </visual>
    <collision>
      <origin rpy="0 0 0" xyz="0 0 -0.05"/>
      <geometry>
        <cylinder length="0.05" radius="0.005"/>
      </geometry>
    </collision>
    <inertial>
      <mass value="0.1"/>
      <origin rpy="0 0 0" xyz="0 0 0"/>
      <inertia ixx="1e-3" ixy="0" ixz="0" iyy="1e-3" iyz="0" izz="1e-3"/>
    </inertial>
  </link>
  <joint name="manipulator/finger_0_connection" type="fixed">
    <parent link="manipulator/link_0"/>
    <child link="manipulator/finger_0_link_0"/>
    <origin rpy="0 0 -1.5707963267948966" xyz="0 -0.15 0"/>
  </joint>
  <link name="manipulator/finger_0_link_1">
    <visual>
      <origin rpy="0 0 0" xyz="0 0 -0.025"/>
      <geometry>
        <cylinder length="0.05" radius="0.005"/>
      </geometry>
    </visual>
    <collision>
      <origin rpy="0 0 0" xyz="0 0 -0.025"/>
      <geometry>
        <cylinder length="0.1" radius="0.005"/>
      </geometry>
    </collision>
    <inertial>
      <mass value="0.1"/>
      <origin rpy="0 0 0" xyz="0 0 0"/>
      <inertia ixx="1e-3" ixy="0" ixz="0" iyy="1e-3" iyz="0" izz="1e-3"/>
    </inertial>
  </link>
  <joint name="manipulator/finger_0_joint" type="revolute">
    <parent link="manipulator/finger_0_link_0"/>
    <child link="manipulator/finger_0_link_1"/>
    <origin rpy="0 0 0" xyz="0. 0. -0.1"/>
    <axis xyz="0 1 0"/>
    <limit effort="100" lower="0" upper="1.5707963267948966" velocity="1.0"/>
  </joint>
  <link name="manipulator/finger_1_link_0">
    <visual>
      <origin rpy="0 0 0" xyz="0 0 -0.05"/>
      <geometry>
        <cylinder length="0.1" radius="0.005"/>
      </geometry>
    </visual>
    <collision>
      <origin rpy="0 0 0" xyz="0 0 -0.05"/>
      <geometry>
        <cylinder length="0.05" radius="0.005"/>
      </geometry>
    </collision>
    <inertial>
      <mass value="0.1"/>
      <origin rpy="0 0 0" xyz="0 0 0"/>
      <inertia ixx="1e-3" ixy="0" ixz="0" iyy="1e-3" iyz="0" izz="1e-3"/>
    </inertial>
  </link>
  <joint name="manipulator/finger_1_connection" type="fixed">
    <parent link="manipulator/link_0"/>
    <child link="manipulator/finger_1_link_0"/>
    <origin rpy="0 0 1.5707963267948966s" xyz="0 0.15 0"/>
  </joint>
  <link name="manipulator/finger_1_link_1">
    <visual>
      <origin rpy="0 0 0" xyz="0 0 -0.025"/>
      <geometry>
        <cylinder length="0.05" radius="0.005"/>
      </geometry>
    </visual>
    <collision>
      <origin rpy="0 0 0" xyz="0 0 -0.025"/>
      <geometry>
        <cylinder length="0.1" radius="0.005"/>
      </geometry>
    </collision>
    <inertial>
      <mass value="0.1"/>
      <origin rpy="0 0 0" xyz="0 0 0"/>
      <inertia ixx="1e-3" ixy="0" ixz="0" iyy="1e-3" iyz="0" izz="1e-3"/>
    </inertial>
  </link>
  <joint name="manipulator/finger_1_joint" type="revolute">
    <parent link="manipulator/finger_1_link_0"/>
    <child link="manipulator/finger_1_link_1"/>
    <origin rpy="0 0 0" xyz="0. 0. -0.1"/>
    <axis xyz="0 1 0"/>
    <limit effort="100" lower="0" upper="1.5707963267948966" velocity="1.0"/>
  </joint>
  <link name="manipulator/finger_2_link_0">
    <visual>
      <origin rpy="0 0 0" xyz="0 0 -0.05"/>
      <geometry>
        <cylinder length="0.1" radius="0.005"/>
      </geometry>
    </visual>
    <collision>
      <origin rpy="0 0 0" xyz="0 0 -0.05"/>
      <geometry>
        <cylinder length="0.05" radius="0.005"/>
      </geometry>
    </collision>
    <inertial>
      <mass value="0.1"/>
      <origin rpy="0 0 0" xyz="0 0 0"/>
      <inertia ixx="1e-3" ixy="0" ixz="0" iyy="1e-3" iyz="0" izz="1e-3"/>
    </inertial>
  </link>
  <joint name="manipulator/finger_2_connection" type="fixed">
    <parent link="manipulator/link_1"/>
    <child link="manipulator/finger_2_link_0"/>
    <origin rpy="0 0 -3.141592653589793" xyz="-0.15 0 0"/>
  </joint>
  <link name="manipulator/finger_2_link_1">
    <visual>
      <origin rpy="0 0 0" xyz="0 0 -0.025"/>
      <geometry>
        <cylinder length="0.05" radius="0.005"/>
      </geometry>
    </visual>
    <collision>
      <origin rpy="0 0 0" xyz="0 0 -0.025"/>
      <geometry>
        <cylinder length="0.1" radius="0.005"/>
      </geometry>
    </collision>
    <inertial>
      <mass value="0.1"/>
      <origin rpy="0 0 0" xyz="0 0 0"/>
      <inertia ixx="1e-3" ixy="0" ixz="0" iyy="1e-3" iyz="0" izz="1e-3"/>
    </inertial>
  </link>
  <joint name="manipulator/finger_2_joint" type="revolute">
    <parent link="manipulator/finger_2_link_0"/>
    <child link="manipulator/finger_2_link_1"/>
    <origin rpy="0 0 0" xyz="0. 0. -0.1"/>
    <axis xyz="0 1 0"/>
    <limit effort="100" lower="0" upper="1.5707963267948966" velocity="1.0"/>
  </joint>
  <link name="manipulator/finger_3_link_0">
    <visual>
      <origin rpy="0 0 0" xyz="0 0 -0.05"/>
      <geometry>
        <cylinder length="0.1" radius="0.005"/>
      </geometry>
    </visual>
    <collision>
      <origin rpy="0 0 0" xyz="0 0 -0.05"/>
      <geometry>
        <cylinder length="0.05" radius="0.005"/>
      </geometry>
    </collision>
    <inertial>
      <mass value="0.1"/>
      <origin rpy="0 0 0" xyz="0 0 0"/>
      <inertia ixx="1e-3" ixy="0" ixz="0" iyy="1e-3" iyz="0" izz="1e-3"/>
    </inertial>
  </link>
  <joint name="manipulator/finger_3_connection" type="fixed">
    <parent link="manipulator/link_1"/>
    <child link="manipulator/finger_3_link_0"/>
    <origin rpy="0 0 0" xyz="0.15 0 0"/>
  </joint>
  <link name="manipulator/finger_3_link_1">
    <visual>
      <origin rpy="0 0 0" xyz="0 0 -0.025"/>
      <geometry>
        <cylinder length="0.05" radius="0.005"/>
      </geometry>
    </visual>
    <collision>
      <origin rpy="0 0 0" xyz="0 0 -0.025"/>
      <geometry>
        <cylinder length="0.1" radius="0.005"/>
      </geometry>
    </collision>
    <inertial>
      <mass value="0.1"/>
      <origin rpy="0 0 0" xyz="0 0 0"/>
      <inertia ixx="1e-3" ixy="0" ixz="0" iyy="1e-3" iyz="0" izz="1e-3"/>
    </inertial>
  </link>
  <joint name="manipulator/finger_3_joint" type="revolute">
    <parent link="manipulator/finger_3_link_0"/>
    <child link="manipulator/finger_3_link_1"/>
    <origin rpy="0 0 0" xyz="0. 0. -0.1"/>
    <axis xyz="0 1 0"/>
    <limit effort="100" lower="0" upper="1.5707963267948966" velocity="1.0"/>
  </joint>
</robot>

