<?xml version="1.0" ?>
<!-- =================================================================================== -->
<!-- |    This document was autogenerated by xacro from darias.urdf.xacro              | -->
<!-- |    EDITING THIS FILE BY HAND IS NOT RECOMMENDED                                 | -->
<!-- =================================================================================== -->
<robot name="darias" xmlns:controller="http://playerstage.sourceforge.net/gazebo/xmlschema/#controller" xmlns:interface="http://playerstage.sourceforge.net/gazebo/xmlschema/#interface" xmlns:sensor="http://playerstage.sourceforge.net/gazebo/xmlschema/#sensor" xmlns:xacro="http://www.ros.org/wiki/xacro">
  <!-- the mass values and inertia may not be completly correct as the moment so this model should just be used as a kinematic one now-->
  <material name="DarkGrey">
    <color rgba="0.3 0.3 0.3 1.0"/>
  </material>
  <material name="Black">
    <color rgba="0 0 0 1.0"/>
  </material>
  <material name="Grey">
    <color rgba="0.7 0.7 0.7 1.0"/>
  </material>
  <material name="Blue">
    <color rgba="0.0 0.5 0.8 1.0"/>
  </material>
  <material name="HandGray">
    <color rgba="0.953 0.996 0.694 1.0"/>
  </material>
  <!-- offset values for left and right arm, triangle forms 60 degree, offset over tabel: offset from base top: -->
  <!-- not used now need to measure offset-->
  <!-- not used now-->
  <!-- Darias base (basically just a box on which the arms are mounted on) -->
  <link name="world"/>
  <joint name="fixed" type="fixed">
    <origin rpy="0.0 0.0 0.0" xyz="0.0 0.0 1.307 "/>
    <parent link="world"/>
    <child link="darias"/>
  </joint>
  <link name="darias">
    <inertial>
      <mass value="200.0"/>
      <origin rpy="0 0 0" xyz="0 0 0.15"/>
      <!-- need to check all this inertia stuff -->
      <inertia ixx="2.38541666667" ixy="0" ixz="0" iyy="0.708333333333" iyz="0" izz="3.01041666667"/>
    </inertial>
    <visual>
      <origin rpy="0 0 0" xyz="-0.1 0 -0.472"/>
      <geometry>
        <box size="0.2 0.2 1.5"/>
      </geometry>
      <material name="DarkGrey"/>
    </visual>
    <collision>
      <origin rpy="0 0 0" xyz="-0.1 0 -0.472"/>
      <geometry>
        <box size="0.2 0.2 1.5"/>
      </geometry>
    </collision>
  </link>
  <gazebo reference="darias">
    <material value="Gazebo/Black"/>
    <turnGravityOff>0</turnGravityOff>
    <!-- use gravity for the base even if disabled for the arms in order to prevent darias from falling-->
  </gazebo>
  <!-- Darias right arm -->
  <joint name="darias_R_base" type="fixed">
    <origin rpy="1.570796 -1.570796 0.523598776" xyz="-0.11 -0.06 0.193"/>
    <parent link="darias"/>
    <child link="calib_R_base_link"/>
  </joint>
  <link name="calib_R_base_link">
    <inertial>
      <mass value="1.0"/>
      <origin rpy="0 0 0" xyz="0 0 0.055"/>
      <inertia ixx="0.00190833333333" ixy="0" ixz="0" iyy="0.0018" iyz="0" izz="0.00190833333333"/>
    </inertial>
    <visual>
      <origin rpy="0 0 0" xyz="0 0 0"/>
      <geometry>
        <mesh filename="meshes/arm/convex/arm_base_convex.stl"/>
      </geometry>
      <material name="Blue"/>
    </visual>
    <collision>
      <origin rpy="0 0 0" xyz="0 0 0"/>
      <geometry>
        <mesh filename="meshes/arm/convex/arm_base_convex.stl"/>
      </geometry>
    </collision>
  </link>
  <gazebo reference="calib_R_base_link">
    <material value="Gazebo/Blue"/>
    <turnGravityOff>1</turnGravityOff>
  </gazebo>
  <joint name="R_SFE" type="revolute">
    <!-- former revolute -->
    <origin rpy="0 0 0" xyz="0 0 0.11"/>
    <axis xyz="0 0 1"/>
    <limit effort="10000.0" lower="-2.967059" upper="2.967059" velocity="1.91986217719"/>
    <!-- 204 -->
    <safety_controller k_position="100" k_velocity="2" soft_lower_limit="-2.93215314335" soft_upper_limit="2.93215314335"/>
    <dynamics damping="0.1"/>
    <parent link="calib_R_base_link"/>
    <child link="R_1_link"/>
  </joint>
  <link name="R_1_link">
    <inertial>
      <mass value="1.0"/>
      <origin rpy="0 0 0" xyz="0 0 0.130"/>
      <inertia ixx="0.00683333333333" ixy="0" ixz="0" iyy="0.0015" iyz="0" izz="0.00593333333333"/>
    </inertial>
    <visual>
      <origin rpy="0 0 3.14159265359" xyz="0 0 0"/>
      <geometry>
        <mesh filename="meshes/arm/convex/arm_segment_a_convex.stl"/>
      </geometry>
      <material name="Blue"/>
    </visual>
    <collision>
      <origin rpy="0 0 3.14159265359" xyz="0 0 0"/>
      <geometry>
        <mesh filename="meshes/arm/convex/arm_segment_a_convex.stl"/>
      </geometry>
    </collision>
  </link>
  <gazebo reference="R_1_link">
    <material value="Gazebo/Blue"/>
    <turnGravityOff>1</turnGravityOff>
  </gazebo>
  <transmission name="R_0_trans">
    <type>transmission_interface/SimpleTransmission</type>
    <joint name="R_SFE">
      <hardwareInterface>EffortJointInterface</hardwareInterface>
    </joint>
    <actuator name="R_0_motor">
      <mechanicalReduction>1</mechanicalReduction>
    </actuator>
  </transmission>
  <joint name="R_SAA" type="revolute">
    <origin rpy="0 0 0" xyz="0 0 0.20"/>
    <axis xyz="0 -1 0"/>
    <limit effort="10000.0" lower="-2.094395" upper="2.094395" velocity="1.91986217719"/>
    <!-- effort 306 -->
    <safety_controller k_position="100" k_velocity="2" soft_lower_limit="-2.05948851735" soft_upper_limit="2.05948851735"/>
    <dynamics damping="0.1"/>
    <parent link="R_1_link"/>
    <child link="R_2_link"/>
  </joint>
  <link name="R_2_link">
    <inertial>
      <mass value="1.0"/>
      <origin rpy="0 0 0" xyz="0 0.06 0.07"/>
      <inertia ixx="0.00683333333333" ixy="0" ixz="0" iyy="0.0015" iyz="0" izz="0.00593333333333"/>
    </inertial>
    <visual>
      <origin rpy="3.14159265359 0 3.14159265359" xyz="0 0 0.2"/>
      <geometry>
        <mesh filename="meshes/arm/convex/arm_segment_b_convex.stl"/>
      </geometry>
      <material name="Blue"/>
    </visual>
    <collision>
      <origin rpy="3.14159265359 0 3.14159265359" xyz="0 0 0.2"/>
      <geometry>
        <mesh filename="meshes/arm/convex/arm_segment_b_convex.stl"/>
      </geometry>
    </collision>
  </link>
  <gazebo reference="R_2_link">
    <material value="Gazebo/Blue"/>
    <turnGravityOff>1</turnGravityOff>
  </gazebo>
  <transmission name="R_1_trans">
    <type>transmission_interface/SimpleTransmission</type>
    <joint name="R_SAA">
      <hardwareInterface>EffortJointInterface</hardwareInterface>
    </joint>  
    <actuator name="R_1_motor">
      
      <mechanicalReduction>1</mechanicalReduction>
    </actuator>
  </transmission>
  <joint name="R_HR" type="revolute">
    <origin rpy="0 0 0" xyz="0 0 0.20"/>
    <axis xyz="0 0 1"/>
    <limit effort="10000.0" lower="-2.967059" upper="2.967059" velocity="2.26892802759"/>
    <!-- 204 -->
    <safety_controller k_position="100" k_velocity="2" soft_lower_limit="-2.93215314335" soft_upper_limit="2.93215314335"/>
    <dynamics damping="0.1"/>
    <parent link="R_2_link"/>
    <child link="R_3_link"/>
  </joint>
  <link name="R_3_link">
    <inertial>
      <mass value="1.0"/>
      <origin rpy="0 0 0" xyz="0 0.06 0.130"/>
      <inertia ixx="0.00683333333333" ixy="0" ixz="0" iyy="0.0015" iyz="0" izz="0.00593333333333"/>
    </inertial>
    <visual>
      <origin rpy="0 0 0" xyz="0 0 0"/>
      <geometry>
        <mesh filename="meshes/arm/convex/arm_segment_a_convex.stl"/>
      </geometry>
      <material name="Blue"/>
    </visual>
    <collision>
      <origin rpy="0 0 0" xyz="0 0 0"/>
      <geometry>
        <mesh filename="meshes/arm/convex/arm_segment_a_convex.stl"/>
      </geometry>
    </collision>
  </link>
  <gazebo reference="R_3_link">
    <material value="Gazebo/Blue"/>
    <turnGravityOff>1</turnGravityOff>
  </gazebo>
  <transmission name="R_2_trans">
    <type>transmission_interface/SimpleTransmission</type>
    <joint name="R_HR">
      <hardwareInterface>EffortJointInterface</hardwareInterface>
    </joint>
    <actuator name="R_2_motor">
      
      <mechanicalReduction>1</mechanicalReduction>
    </actuator>
  </transmission>
  <joint name="R_EB" type="revolute">
    <origin rpy="0 0 0" xyz="0 0 0.20"/>
    <axis xyz="0 1 0"/>
    <limit effort="10000.0" lower="-2.094395" upper="2.094395" velocity="2.26892802759"/>
    <!-- 306 -->
    <safety_controller k_position="100" k_velocity="2" soft_lower_limit="-2.05948851735" soft_upper_limit="2.05948851735"/>
    <dynamics damping="0.1"/>
    <parent link="R_3_link"/>
    <child link="R_4_link"/>
  </joint>
  <link name="R_4_link">
    <inertial>
      <mass value="1.0"/>
      <origin rpy="0 0 0" xyz="0 -0.06 0.07"/>
      <inertia ixx="0.00683333333333" ixy="0" ixz="0" iyy="0.0015" iyz="0" izz="0.00593333333333"/>
    </inertial>
    <visual>
      <origin rpy="0 3.14159265359 3.14159265359" xyz="0 0 0.2"/>
      <geometry>
        <mesh filename="meshes/arm/convex/arm_segment_b_convex.stl"/>
      </geometry>
      <material name="Blue"/>
    </visual>
    <collision>
      <origin rpy="0 3.14159265359 3.14159265359" xyz="0 0 0.2"/>
      <geometry>
        <mesh filename="meshes/arm/convex/arm_segment_b_convex.stl"/>
      </geometry>
    </collision>
  </link>
  <gazebo reference="R_4_link">
    <material value="Gazebo/Blue"/>
    <turnGravityOff>1</turnGravityOff>
  </gazebo>
  <transmission name="R_3_trans">
    <type>transmission_interface/SimpleTransmission</type>
    <joint name="R_EB">
      <hardwareInterface>EffortJointInterface</hardwareInterface>
    </joint>
    <actuator name="R_3_motor">
     
      <mechanicalReduction>1</mechanicalReduction>
    </actuator>
  </transmission>
  <joint name="R_WR" type="revolute">
    <origin rpy="0 0 0" xyz="0 0 0.20"/>
    <axis xyz="0 0 1"/>
    <limit effort="10000.0" lower="-2.967059" upper="2.967059" velocity="2.26892802759"/>
    <!-- 204 -->
    <safety_controller k_position="100" k_velocity="2" soft_lower_limit="-2.93215314335" soft_upper_limit="2.93215314335"/>
    <dynamics damping="0.1"/>
    <parent link="R_4_link"/>
    <child link="R_5_link"/>
  </joint>
  <link name="R_5_link">
    <inertial>
      <mass value="1.0"/>
      <origin rpy="0 0 0" xyz="0 0 0.124"/>
      <inertia ixx="0.00632533333333" ixy="0" ixz="0" iyy="0.0015" iyz="0" izz="0.00542533333333"/>
    </inertial>
    <visual>
      <origin rpy="0 0 3.14159265359" xyz="0 0 0"/>
      <geometry name="R_5_geom">
        <mesh filename="meshes/arm/convex/arm_segment_last_convex.stl"/>
      </geometry>
      <material name="Blue"/>
    </visual>
    <collision>
      <origin rpy="0 0 3.14159265359" xyz="0 0 0"/>
      <geometry>
        <mesh filename="meshes/arm/convex/arm_segment_last_convex.stl"/>
      </geometry>
    </collision>
  </link>
  <gazebo reference="R_5_link">
    <material value="Gazebo/Blue"/>
    <turnGravityOff>1</turnGravityOff>
  </gazebo>
  <transmission name="R_4_trans">
    <type>transmission_interface/SimpleTransmission</type>
    <joint name="R_WR">
      <hardwareInterface>EffortJointInterface</hardwareInterface>
    </joint>
    <actuator name="R_4_motor">
      <mechanicalReduction>1</mechanicalReduction>
    </actuator>
  </transmission>
  <joint name="R_WFE" type="revolute">
    <origin rpy="0 0 0" xyz="0 0 0.19"/>
    <axis xyz="0 -1 0"/>
    <limit effort="10000.0" lower="-2.094395" upper="2.094395" velocity="3.14159265359"/>
    <!-- 306 -->
    <safety_controller k_position="100" k_velocity="2" soft_lower_limit="-2.05948851735" soft_upper_limit="2.05948851735"/>
    <dynamics damping="0.1"/>
    <parent link="R_5_link"/>
    <child link="R_6_link"/>
  </joint>
  <link name="R_6_link">
    <inertial>
      <mass value="1.0"/>
      <origin rpy="0 0 0" xyz="0 0 0.0625"/>
      <inertia ixx="0.00260416666667" ixy="0" ixz="0" iyy="0.00260416666667" iyz="0" izz="0.00260416666667"/>
    </inertial>
    <visual>
      <origin rpy="0 0 3.14159265359" xyz="0 0 0"/>
      <geometry>
        <mesh filename="meshes/arm/convex/arm_wrist_convex.stl"/>
      </geometry>
      <material name="HandGray"/>
    </visual>
    <collision>
      <origin rpy="0 0 3.14159265359" xyz="0 0 0"/>
      <geometry>
        <mesh filename="meshes/arm/convex/arm_wrist_convex.stl"/>
      </geometry>
    </collision>
  </link>
  <gazebo reference="R_6_link">
    <material value="Gazebo/White"/>
    <turnGravityOff>1</turnGravityOff>
  </gazebo>
  <transmission name="R_5_trans" >
    <type>transmission_interface/SimpleTransmission</type>
    <joint name="R_WFE">
      <hardwareInterface>EffortJointInterface</hardwareInterface>
    </joint>
    <actuator name="R_5_motor">
      <mechanicalReduction>1</mechanicalReduction>
    </actuator>
  </transmission>
  <joint name="R_WAA" type="revolute">
    <origin rpy="0 0 0" xyz="0.0 0 0.078"/>
    <axis xyz="0 0 1"/>
    <limit effort="10000.0" lower="-2.967059" upper="2.967059" velocity="3.14159265359"/>
    <safety_controller k_position="100" k_velocity="2" soft_lower_limit="-2.93215314335" soft_upper_limit="2.93215314335"/>
    <dynamics damping="0.1"/>
    <parent link="R_6_link"/>
    <child link="right_endeffector_link"/>
  </joint>
  <transmission name="R_6_trans">
    <type>transmission_interface/SimpleTransmission</type>
    <joint name="R_WAA">
      <hardwareInterface>EffortJointInterface</hardwareInterface>
    </joint>
    <actuator name="R_6_motor">
      <mechanicalReduction>1</mechanicalReduction>
    </actuator>
  </transmission>
  <link name="right_endeffector_link">
    <inertial>
      <mass value="1"/>
      <origin rpy="0 0 0" xyz="0 0 0.0625"/>
      <inertia ixx="0.00260416666667" ixy="0" ixz="0" iyy="0.00260416666667" iyz="0" izz="0.00260416666667"/>
    </inertial>
  </link>
  <gazebo reference="right_endeffector_link">
    <material value="Gazebo/White"/>
    <turnGravityOff>1</turnGravityOff>
  </gazebo>
  <!-- Darias left arm -->
  <joint name="darias_L_base" type="fixed">
    <origin rpy="1.570796 1.570796 2.617993878" xyz="-0.11 0.06 0.193"/>
    <parent link="darias"/>
    <child link="calib_L_base_link"/>
  </joint>
  <link name="calib_L_base_link">
    <inertial>
      <mass value="1.0"/>
      <origin rpy="0 0 0" xyz="0 0 0.055"/>
      <inertia ixx="0.00190833333333" ixy="0" ixz="0" iyy="0.0018" iyz="0" izz="0.00190833333333"/>
    </inertial>
    <visual>
      <origin rpy="0 0 0" xyz="0 0 0"/>
      <geometry>
        <mesh filename="meshes/arm/convex/arm_base_convex.stl"/>
      </geometry>
      <material name="Blue"/>
    </visual>
    <collision>
      <origin rpy="0 0 0" xyz="0 0 0"/>
      <geometry>
        <mesh filename="meshes/arm/convex/arm_base_convex.stl"/>
      </geometry>
    </collision>
  </link>
  <gazebo reference="calib_L_base_link">
    <material value="Gazebo/Blue"/>
    <turnGravityOff>1</turnGravityOff>
  </gazebo>
  <joint name="L_SFE" type="revolute">
    <!-- former revolute -->
    <origin rpy="0 0 0" xyz="0 0 0.11"/>
    <axis xyz="0 0 1"/>
    <limit effort="10000.0" lower="-2.967059" upper="2.967059" velocity="1.91986217719"/>
    <!-- 204 -->
    <safety_controller k_position="100" k_velocity="2" soft_lower_limit="-2.93215314335" soft_upper_limit="2.93215314335"/>
    <dynamics damping="0.1"/>
    <parent link="calib_L_base_link"/>
    <child link="L_1_link"/>
  </joint>
  <link name="L_1_link">
    <inertial>
      <mass value="1.0"/>
      <origin rpy="0 0 0" xyz="0 0 0.130"/>
      <inertia ixx="0.00683333333333" ixy="0" ixz="0" iyy="0.0015" iyz="0" izz="0.00593333333333"/>
    </inertial>
    <visual>
      <origin rpy="0 0 3.14159265359" xyz="0 0 0"/>
      <geometry>
        <mesh filename="meshes/arm/convex/arm_segment_a_convex.stl"/>
      </geometry>
      <material name="Blue"/>
    </visual>
    <collision>
      <origin rpy="0 0 3.14159265359" xyz="0 0 0"/>
      <geometry>
        <mesh filename="meshes/arm/convex/arm_segment_a_convex.stl"/>
      </geometry>
    </collision>
  </link>
  <gazebo reference="L_1_link">
    <material value="Gazebo/Blue"/>
    <turnGravityOff>1</turnGravityOff>
  </gazebo>
  <transmission name="L_0_trans">
    <type>transmission_interface/SimpleTransmission</type>
    <joint name="L_SFE">
      <hardwareInterface>EffortJointInterface</hardwareInterface>
    </joint>
    <actuator name="L_0_motor">
      <mechanicalReduction>1</mechanicalReduction>
    </actuator>
  </transmission>
  <joint name="L_SAA" type="revolute">
    <origin rpy="0 0 0" xyz="0 0 0.20"/>
    <axis xyz="0 -1 0"/>
    <limit effort="10000.0" lower="-2.094395" upper="2.094395" velocity="1.91986217719"/>
    <!-- effort 306 -->
    <safety_controller k_position="100" k_velocity="2" soft_lower_limit="-2.05948851735" soft_upper_limit="2.05948851735"/>
    <dynamics damping="0.1"/>
    <parent link="L_1_link"/>
    <child link="L_2_link"/>
  </joint>
  <link name="L_2_link">
    <inertial>
      <mass value="1.0"/>
      <origin rpy="0 0 0" xyz="0 0.06 0.07"/>
      <inertia ixx="0.00683333333333" ixy="0" ixz="0" iyy="0.0015" iyz="0" izz="0.00593333333333"/>
    </inertial>
    <visual>
      <origin rpy="3.14159265359 0 3.14159265359" xyz="0 0 0.2"/>
      <geometry>
        <mesh filename="meshes/arm/convex/arm_segment_b_convex.stl"/>
      </geometry>
      <material name="Blue"/>
    </visual>
    <collision>
      <origin rpy="3.14159265359 0 3.14159265359" xyz="0 0 0.2"/>
      <geometry>
        <mesh filename="meshes/arm/convex/arm_segment_b_convex.stl"/>
      </geometry>
    </collision>
  </link>
  <gazebo reference="L_2_link">
    <material value="Gazebo/Blue"/>
    <turnGravityOff>1</turnGravityOff>
  </gazebo>
  <transmission name="L_1_trans">
    <type>transmission_interface/SimpleTransmission</type>
    <joint name="L_SAA">
      <hardwareInterface>EffortJointInterface</hardwareInterface>
    </joint>
    <actuator name="L_1_motor">
      <mechanicalReduction>1</mechanicalReduction>
    </actuator>
  </transmission>
  <joint name="L_HR" type="revolute">
    <origin rpy="0 0 0" xyz="0 0 0.20"/>
    <axis xyz="0 0 1"/>
    <limit effort="10000.0" lower="-2.967059" upper="2.967059" velocity="2.26892802759"/>
    <!-- 204 -->
    <safety_controller k_position="100" k_velocity="2" soft_lower_limit="-2.93215314335" soft_upper_limit="2.93215314335"/>
    <dynamics damping="0.1"/>
    <parent link="L_2_link"/>
    <child link="L_3_link"/>
  </joint>
  <link name="L_3_link">
    <inertial>
      <mass value="1.0"/>
      <origin rpy="0 0 0" xyz="0 0.06 0.130"/>
      <inertia ixx="0.00683333333333" ixy="0" ixz="0" iyy="0.0015" iyz="0" izz="0.00593333333333"/>
    </inertial>
    <visual>
      <origin rpy="0 0 0" xyz="0 0 0"/>
      <geometry>
        <mesh filename="meshes/arm/convex/arm_segment_a_convex.stl"/>
      </geometry>
      <material name="Blue"/>
    </visual>
    <collision>
      <origin rpy="0 0 0" xyz="0 0 0"/>
      <geometry>
        <mesh filename="meshes/arm/convex/arm_segment_a_convex.stl"/>
      </geometry>
    </collision>
  </link>
  <gazebo reference="L_3_link">
    <material value="Gazebo/Blue"/>
    <turnGravityOff>1</turnGravityOff>
  </gazebo>
  <transmission name="L_2_trans">
    <type>transmission_interface/SimpleTransmission</type>
    <joint name="L_HR">
      <hardwareInterface>EffortJointInterface</hardwareInterface>
    </joint>
    <actuator name="L_2_motor">
      <mechanicalReduction>1</mechanicalReduction>
    </actuator>
  </transmission>
  <joint name="L_EB" type="revolute">
    <origin rpy="0 0 0" xyz="0 0 0.20"/>
    <axis xyz="0 1 0"/>
    <limit effort="10000.0" lower="-2.094395" upper="2.094395" velocity="2.26892802759"/>
    <!-- 306 -->
    <safety_controller k_position="100" k_velocity="2" soft_lower_limit="-2.05948851735" soft_upper_limit="2.05948851735"/>
    <dynamics damping="0.1"/>
    <parent link="L_3_link"/>
    <child link="L_4_link"/>
  </joint>
  <link name="L_4_link">
    <inertial>
      <mass value="1.0"/>
      <origin rpy="0 0 0" xyz="0 -0.06 0.07"/>
      <inertia ixx="0.00683333333333" ixy="0" ixz="0" iyy="0.0015" iyz="0" izz="0.00593333333333"/>
    </inertial>
    <visual>
      <origin rpy="0 3.14159265359 3.14159265359" xyz="0 0 0.2"/>
      <geometry>
        <mesh filename="meshes/arm/convex/arm_segment_b_convex.stl"/>
      </geometry>
      <material name="Blue"/>
    </visual>
    <collision>
      <origin rpy="0 3.14159265359 3.14159265359" xyz="0 0 0.2"/>
      <geometry>
        <mesh filename="meshes/arm/convex/arm_segment_b_convex.stl"/>
      </geometry>
    </collision>
  </link>
  <gazebo reference="L_4_link">
    <material value="Gazebo/Blue"/>
    <turnGravityOff>1</turnGravityOff>
  </gazebo>
  <transmission name="L_3_trans">
    <type>transmission_interface/SimpleTransmission</type>
    <joint name="L_EB">
      <hardwareInterface>EffortJointInterface</hardwareInterface>
    </joint>
    <actuator name="L_3_motor">
      <mechanicalReduction>1</mechanicalReduction>
    </actuator>
  </transmission>
  <joint name="L_WR" type="revolute">
    <origin rpy="0 0 0" xyz="0 0 0.20"/>
    <axis xyz="0 0 1"/>
    <limit effort="10000.0" lower="-2.967059" upper="2.967059" velocity="2.26892802759"/>
    <!-- 204 -->
    <safety_controller k_position="100" k_velocity="2" soft_lower_limit="-2.93215314335" soft_upper_limit="2.93215314335"/>
    <dynamics damping="0.1"/>
    <parent link="L_4_link"/>
    <child link="L_5_link"/>
  </joint>
  <link name="L_5_link">
    <inertial>
      <mass value="1.0"/>
      <origin rpy="0 0 0" xyz="0 0 0.124"/>
      <inertia ixx="0.00632533333333" ixy="0" ixz="0" iyy="0.0015" iyz="0" izz="0.00542533333333"/>
    </inertial>
    <visual>
      <origin rpy="0 0 3.14159265359" xyz="0 0 0"/>
      <geometry name="L_5_geom">
        <mesh filename="meshes/arm/convex/arm_segment_last_convex.stl"/>
      </geometry>
      <material name="Blue"/>
    </visual>
    <collision>
      <origin rpy="0 0 3.14159265359" xyz="0 0 0"/>
      <geometry>
        <mesh filename="meshes/arm/convex/arm_segment_last_convex.stl"/>
      </geometry>
    </collision>
  </link>
  <gazebo reference="L_5_link">
    <material value="Gazebo/Blue"/>
    <turnGravityOff>1</turnGravityOff>
  </gazebo>
  <transmission name="L_4_trans">
    <type>transmission_interface/SimpleTransmission</type>
    <joint name="L_WR">
      <hardwareInterface>EffortJointInterface</hardwareInterface>
    </joint>
    <actuator name="L_4_motor">
      <mechanicalReduction>1</mechanicalReduction>
    </actuator>
  </transmission>
  <joint name="L_WFE" type="revolute">
    <origin rpy="0 0 0" xyz="0 0 0.19"/>
    <axis xyz="0 -1 0"/>
    <limit effort="10000.0" lower="-2.094395" upper="2.094395" velocity="3.14159265359"/>
    <!-- 306 -->
    <safety_controller k_position="100" k_velocity="2" soft_lower_limit="-2.05948851735" soft_upper_limit="2.05948851735"/>
    <dynamics damping="0.1"/>
    <parent link="L_5_link"/>
    <child link="L_6_link"/>
  </joint>
  <link name="L_6_link">
    <inertial>
      <mass value="1.0"/>
      <origin rpy="0 0 0" xyz="0 0 0.0625"/>
      <inertia ixx="0.00260416666667" ixy="0" ixz="0" iyy="0.00260416666667" iyz="0" izz="0.00260416666667"/>
    </inertial>
    <visual>
      <origin rpy="0 0 3.14159265359" xyz="0 0 0"/>
      <geometry>
        <mesh filename="meshes/arm/convex/arm_wrist_convex.stl"/>
      </geometry>
      <material name="HandGray"/>
    </visual>
    <collision>
      <origin rpy="0 0 3.14159265359" xyz="0 0 0"/>
      <geometry>
        <mesh filename="meshes/arm/convex/arm_wrist_convex.stl"/>
      </geometry>
    </collision>
  </link>
  <gazebo reference="L_6_link">
    <material value="Gazebo/White"/>
    <turnGravityOff>1</turnGravityOff>
  </gazebo>
  <transmission name="L_5_trans">
    <type>transmission_interface/SimpleTransmission</type>
    <joint name="L_WFE">
      <hardwareInterface>EffortJointInterface</hardwareInterface>
    </joint>
    <actuator name="L_5_motor">
      <mechanicalReduction>1</mechanicalReduction>
    </actuator>
  </transmission>
  <joint name="L_WAA" type="revolute">
    <origin rpy="0 0 0" xyz="0.0 0 0.078"/>
    <axis xyz="0 0 1"/>
    <limit effort="10000.0" lower="-2.094395" upper="2.094395" velocity="3.14159265359"/>
    <safety_controller k_position="100" k_velocity="2" soft_lower_limit="-2.93215314335" soft_upper_limit="2.93215314335"/>
    <dynamics damping="0.1"/>
    <parent link="L_6_link"/>
    <child link="left_endeffector_link"/>
  </joint>
  <transmission name="L_6_trans">
    <type>transmission_interface/SimpleTransmission</type>
    <joint name="L_WAA">
      <hardwareInterface>EffortJointInterface</hardwareInterface>
    </joint>
    <actuator name="L_6_motor">
      <mechanicalReduction>1</mechanicalReduction>
    </actuator>
  </transmission>
  <link name="left_endeffector_link">
    <inertial>
      <mass value="1"/>
      <origin rpy="0 0 0" xyz="0 0 0.0625"/>
      <inertia ixx="0.00260416666667" ixy="0" ixz="0" iyy="0.00260416666667" iyz="0" izz="0.00260416666667"/>
    </inertial>
  </link>
  <gazebo reference="left_endeffector_link">
    <material value="Gazebo/White"/>
    <turnGravityOff>1</turnGravityOff>
  </gazebo>
  <!-- right Hand of darias -->
  <joint name="R_mount" type="fixed">
    <limit effort="10000.0" lower="-2.96705972839" upper="2.96705972839" velocity="3.14159265359"/>
    <parent link="right_endeffector_link"/>
    <child link="R_palm"/>
    <origin rpy="0 0 -1.57" xyz="0.0 0 0"/>
  </joint>
  <link name="R_palm">
    <inertial>
      <origin rpy="0 0 0" xyz="-0.004 0.002 0.076"/>
      <mass value="0.5"/>
      <inertia ixx="0.00141454166667" ixy="0" ixz="0" iyy="0.000900333333333" iyz="0" izz="0.00175454166667"/>
    </inertial>
    <visual>
      <origin rpy="1.57 0  1.57 " xyz="0.02 0.007  0.025"/>
      <geometry>
        <mesh filename="meshes/hand/righthandbase.stl" scale="0.001 0.001 0.001"/>
      </geometry>
      <material name="HandGray"/>
    </visual>
    <collision>
      <origin rpy="1.57 0  1.57" xyz="0.02 0.007  0.025"/>
      <geometry>
        <mesh filename="meshes/hand/righthandbase.stl" scale="0.001 0.001 0.001"/>
      </geometry>
    </collision>
  </link>
  <gazebo reference="R_palm">
    <material value="Gazebo/White"/>
    <turnGravityOff>1</turnGravityOff>
  </gazebo>
  <joint name="R_SMS" type="revolute">
    <parent link="R_palm"/>
    <child link="R_SMS_link"/>
    <origin rpy="1.570796 -1.536488 1.570796" xyz="0.000971571  -0.043396306  0.095043545"/>
    <axis xyz="0 0 1"/>
    <limit effort="100" lower="-0.261" upper="0.2618" velocity="100"/>
    <dynamics damping="0.005"/>
  </joint>
  <transmission name="R_SMS_trans">
    <type>transmission_interface/SimpleTransmission</type>
    <joint name="R_SMS">
      <hardwareInterface>EffortJointInterface</hardwareInterface>
    </joint>
    <actuator name="R_SMS_motor">
      <mechanicalReduction>1</mechanicalReduction>
    </actuator>
  </transmission>
  <link name="R_SMS_link">
    <inertial>
      <origin rpy="0 0 0" xyz="0.004 0 0"/>
      <mass value="0.1"/>
      <inertia ixx="2.24083333333e-05" ixy="0" ixz="0" iyy="1.42833333333e-05" iyz="0" izz="1.85416666667e-05"/>
    </inertial>
    <visual>
      <origin rpy="0 0 0" xyz="0 0 0"/>
      <geometry>
        <mesh filename="meshes/hand/finger_base.stl"/>
      </geometry>
      <material name="HandGray"/>
    </visual>
    <collision>
      <origin rpy="0 0 0" xyz="0 0 0"/>
      <geometry>
        <mesh filename="meshes/hand/finger_base.stl"/>
      </geometry>
    </collision>
  </link>
  <gazebo reference="R_SMS_link">
    <material value="Gazebo/White"/>
    <turnGravityOff>1</turnGravityOff>
  </gazebo>
  <joint name="R_SMP" type="revolute">
    <parent link="R_SMS_link"/>
    <child link="R_SMP_link"/>
    <origin rpy="1.570796 0 0" xyz="0 0 0"/>
    <axis xyz="0 0 1"/>
    <limit effort="100" lower="0.087" upper="1.4835" velocity="100"/>
    <dynamics damping="0.005"/>
  </joint>
  <transmission name="R_SMP_trans">
    <type>transmission_interface/SimpleTransmission</type>
    <joint name="R_SMP">
      <hardwareInterface>EffortJointInterface</hardwareInterface>
    </joint>
    <actuator name="R_SMP_motor">
      <mechanicalReduction>1</mechanicalReduction>
    </actuator>
  </transmission>
  <link name="R_SMP_link">
    <inertial>
      <origin rpy="0 0 0" xyz="0.035 -0.02 0"/>
      <mass value="0.1"/>
      <inertia ixx="6.68333333333e-05" ixy="0" ixz="0" iyy="7.00416666667e-05" iyz="0" izz="2.48083333333e-05"/>
    </inertial>
    <visual>
      <origin rpy="0 -1.57  -1.57 " xyz="-0.085 0.015  -0.03"/>
      <geometry>
        <mesh filename="meshes/hand/fore_proximalp.stl" scale="0.001 0.001 0.001"/>
      </geometry>
      <material name="HandGray"/>
    </visual>
    <collision>
      <origin rpy="0 -1.57  -1.57" xyz="-0.085 0.015  -0.03"/>
      <geometry>
        <mesh filename="meshes/hand/fore_proximalp.stl" scale="0.001 0.001 0.001"/>
      </geometry>
    </collision>
  </link>
  <gazebo reference="R_SMP_link">
    <material value="Gazebo/White"/>
    <turnGravityOff>1</turnGravityOff>
  </gazebo>
  <joint name="R_SMD" type="revolute">
    <parent link="R_SMP_link"/>
    <child link="R_SMD_link"/>
    <origin rpy="0 0 0" xyz="0.055 0 0"/>
    <axis xyz="0 0 1"/>
    <limit effort="100" lower="0.087" upper="1.1345" velocity="100"/>
    <dynamics damping="0.005"/>
  </joint>
  <transmission name="R_SMD_trans">
    <type>transmission_interface/SimpleTransmission</type>
    <joint name="R_SMD">
      <hardwareInterface>EffortJointInterface</hardwareInterface>
    </joint>
    <actuator name="R_SMD_motor">
      <mechanicalReduction>1</mechanicalReduction>
    </actuator>
  </transmission>
  <link name="R_SMD_link">
    <inertial>
      <origin rpy="0 0 0" xyz="0.015 -0.01 0"/>
      <mass value="0.1"/>
      <inertia ixx="3.00333333333e-05" ixy="0" ixz="0" iyy="2.90666666667e-05" iyz="0" izz="1.40333333333e-05"/>
    </inertial>
    <visual>
      <origin rpy="0 -1.57  -1.55" xyz="-0.14 0.015  -0.03"/>
      <geometry>
        <mesh filename="meshes/hand/fore_middlep.stl" scale="0.001 0.001 0.001"/>
      </geometry>
      <material name="HandGray"/>
    </visual>
    <collision>
      <origin rpy="0 -1.57  -1.55" xyz="-0.14 0.015  -0.03"/>
      <geometry>
        <mesh filename="meshes/hand/fore_middlep.stl" scale="0.001 0.001 0.001"/>
      </geometry>
    </collision>
  </link>
  <gazebo reference="R_SMD_link">
    <material value="Gazebo/White"/>
    <turnGravityOff>1</turnGravityOff>
  </gazebo>
  
  <joint name="R_RIS" type="revolute">
    <parent link="R_palm"/>
    <child link="R_RIS_link"/>
    <origin rpy="1.570796 -1.536488 1.570796" xyz="-0.002529881 -0.016800135 0.114043545"/>
    <axis xyz="0 0 1"/>
    <limit effort="100" lower="-0.261" upper="0.2618" velocity="100"/>
    <dynamics damping="0.005"/>
  </joint>
  <transmission name="R_RIS_trans">
    <type>transmission_interface/SimpleTransmission</type>
    <joint name="R_RIS">
      <hardwareInterface>EffortJointInterface</hardwareInterface>
    </joint>
    <actuator name="R_RIS_motor">
      <mechanicalReduction>1</mechanicalReduction>
    </actuator>
  </transmission>
  <link name="R_RIS_link">
    <inertial>
      <origin rpy="0 0 0" xyz="0.004 0 0"/>
      <mass value="0.1"/>
      <inertia ixx="2.24083333333e-05" ixy="0" ixz="0" iyy="1.42833333333e-05" iyz="0" izz="1.85416666667e-05"/>
    </inertial>
    <visual>
      <origin rpy="0 0 0" xyz="0 0 0"/>
      <geometry>
        <mesh filename="meshes/hand/finger_base.stl"/>
      </geometry>
      <material name="HandGray"/>
    </visual>
    <collision>
      <origin rpy="0 0 0" xyz="0 0 0"/>
      <geometry>
        <mesh filename="meshes/hand/finger_base.stl"/>
      </geometry>
    </collision>
  </link>
  <gazebo reference="R_RIS_link">
    <material value="Gazebo/White"/>
    <turnGravityOff>1</turnGravityOff>
  </gazebo>
  <joint name="R_RIP" type="revolute">
    <parent link="R_RIS_link"/>
    <child link="R_RIP_link"/>
    <origin rpy="1.570796 0 0" xyz="0 0 0"/>
    <axis xyz="0 0 1"/>
    <limit effort="100" lower="0.087" upper="1.4835" velocity="100"/>
    <dynamics damping="0.005"/>
  </joint>
  <transmission name="R_RIP_trans">
    <type>transmission_interface/SimpleTransmission</type>
    <joint name="R_RIP">
      <hardwareInterface>EffortJointInterface</hardwareInterface>
    </joint>
    <actuator name="R_RIP_motor">
      <mechanicalReduction>1</mechanicalReduction>
    </actuator>
  </transmission>
  <link name="R_RIP_link">
    <inertial>
      <origin rpy="0 0 0" xyz="0.035 -0.02 0"/>
      <mass value="0.1"/>
      <inertia ixx="6.68333333333e-05" ixy="0" ixz="0" iyy="7.00416666667e-05" iyz="0" izz="2.48083333333e-05"/>
    </inertial>
    <visual>
      <origin rpy="0 -1.57  -1.57 " xyz="-0.085 0.015  -0.03"/>
      <geometry>
        <mesh filename="meshes/hand/fore_proximalp.stl" scale="0.001 0.001 0.001"/>
      </geometry>
      <material name="HandGray"/>
    </visual>
    <collision>
      <origin rpy="0 -1.57  -1.57" xyz="-0.085 0.015  -0.03"/>
      <geometry>
        <mesh filename="meshes/hand/fore_proximalp.stl" scale="0.001 0.001 0.001"/>
      </geometry>
    </collision>
  </link>
  <gazebo reference="R_RIP_link">
    <material value="Gazebo/White"/>
    <turnGravityOff>1</turnGravityOff>
  </gazebo>
  <joint name="R_RID" type="revolute">
    <parent link="R_RIP_link"/>
    <child link="R_RID_link"/>
    <origin rpy="0 0 0" xyz="0.055 0 0"/>
    <axis xyz="0 0 1"/>
    <limit effort="100" lower="0.087" upper="1.1345" velocity="100"/>
    <dynamics damping="0.005"/>
  </joint>
  <transmission name="R_RID_trans">
    <type>transmission_interface/SimpleTransmission</type>
    <joint name="R_RID">
      <hardwareInterface>EffortJointInterface</hardwareInterface>
    </joint>
    <actuator name="R_RID_motor">
      <mechanicalReduction>1</mechanicalReduction>
    </actuator>
  </transmission>
  <link name="R_RID_link">
    <inertial>
      <origin rpy="0 0 0" xyz="0.015 -0.01 0"/>
      <mass value="0.1"/>
      <inertia ixx="3.00333333333e-05" ixy="0" ixz="0" iyy="2.90666666667e-05" iyz="0" izz="1.40333333333e-05"/>
    </inertial>
    <visual>
      <origin rpy="0 -1.57  -1.55" xyz="-0.14 0.015  -0.03"/>
      <geometry>
        <mesh filename="meshes/hand/fore_middlep.stl" scale="0.001 0.001 0.001"/>
      </geometry>
      <material name="HandGray"/>
    </visual>
    <collision>
      <origin rpy="0 -1.57  -1.55" xyz="-0.14 0.015  -0.03"/>
      <geometry>
        <mesh filename="meshes/hand/fore_middlep.stl" scale="0.001 0.001 0.001"/>
      </geometry>
    </collision>
  </link>
  <gazebo reference="R_RID_link">
    <material value="Gazebo/White"/>
    <turnGravityOff>1</turnGravityOff>
  </gazebo>

  <joint name="R_MIS" type="revolute">
    <parent link="R_palm"/>
    <child link="R_MIS_link"/>
    <origin rpy="1.570796 -1.536488 1.570796" xyz="-0.002529881 0.009800135 0.116743545 "/>
    <axis xyz="0 0 1"/>
    <limit effort="100" lower="-0.261" upper="0.2618" velocity="100"/>
    <dynamics damping="0.005"/>
  </joint>
  <transmission name="R_MIS_trans">
    <type>transmission_interface/SimpleTransmission</type>
    <joint name="R_MIS">
      <hardwareInterface>EffortJointInterface</hardwareInterface>
    </joint>
    <actuator name="R_MIS_motor">
      <mechanicalReduction>1</mechanicalReduction>
    </actuator>
  </transmission>
  <link name="R_MIS_link">
    <inertial>
      <origin rpy="0 0 0" xyz="0.004 0 0"/>
      <mass value="0.1"/>
      <inertia ixx="2.24083333333e-05" ixy="0" ixz="0" iyy="1.42833333333e-05" iyz="0" izz="1.85416666667e-05"/>
    </inertial>
    <visual>
      <origin rpy="0 0 0" xyz="0 0 0"/>
      <geometry>
        <mesh filename="meshes/hand/finger_base.stl"/>
      </geometry>
      <material name="HandGray"/>
    </visual>
    <collision>
      <origin rpy="0 0 0" xyz="0 0 0"/>
      <geometry>
        <mesh filename="meshes/hand/finger_base.stl"/>
      </geometry>
    </collision>
  </link>
  <gazebo reference="R_MIS_link">
    <material value="Gazebo/White"/>
    <turnGravityOff>1</turnGravityOff>
  </gazebo>
  <joint name="R_MIP" type="revolute">
    <parent link="R_MIS_link"/>
    <child link="R_MIP_link"/>
    <origin rpy="1.570796 0 0" xyz="0 0 0"/>
    <axis xyz="0 0 1"/>
    <limit effort="100" lower="0.087" upper="1.4835" velocity="100"/>
    <dynamics damping="0.005"/>
  </joint>
  <transmission name="R_MIP_trans">
    <type>transmission_interface/SimpleTransmission</type>
    <joint name="R_MIP">
      <hardwareInterface>EffortJointInterface</hardwareInterface>
    </joint>
    <actuator name="R_MIP_motor">
      <mechanicalReduction>1</mechanicalReduction>
    </actuator>
  </transmission>
  <link name="R_MIP_link">
    <inertial>
      <origin rpy="0 0 0" xyz="0.035 -0.02 0"/>
      <mass value="0.1"/>
      <inertia ixx="6.68333333333e-05" ixy="0" ixz="0" iyy="7.00416666667e-05" iyz="0" izz="2.48083333333e-05"/>
    </inertial>
    <visual>
      <origin rpy="0 -1.57  -1.57 " xyz="-0.085 0.015  -0.03"/>
      <geometry>
        <mesh filename="meshes/hand/fore_proximalp.stl" scale="0.001 0.001 0.001"/>
      </geometry>
      <material name="HandGray"/>
    </visual>
    <collision>
      <origin rpy="0 -1.57  -1.57" xyz="-0.085 0.015  -0.03"/>
      <geometry>
        <mesh filename="meshes/hand/fore_proximalp.stl" scale="0.001 0.001 0.001"/>
      </geometry>
    </collision>
  </link>
  <gazebo reference="R_MIP_link">
    <material value="Gazebo/White"/>
    <turnGravityOff>1</turnGravityOff>
  </gazebo>
  <joint name="R_MID" type="revolute">
    <parent link="R_MIP_link"/>
    <child link="R_MID_link"/>
    <origin rpy="0 0 0" xyz="0.055 0 0"/>
    <axis xyz="0 0 1"/>
    <limit effort="100" lower="0.087" upper="1.1345" velocity="100"/>
    <dynamics damping="0.005"/>
  </joint>
  <transmission name="R_MID_trans">
    <type>transmission_interface/SimpleTransmission</type>
    <joint name="R_MID">
      <hardwareInterface>EffortJointInterface</hardwareInterface>
    </joint>
    <actuator name="R_MID_motor">
      <mechanicalReduction>1</mechanicalReduction>
    </actuator>
  </transmission>
  <link name="R_MID_link">
    <inertial>
      <origin rpy="0 0 0" xyz="0.015 -0.01 0"/>
      <mass value="0.1"/>
      <inertia ixx="3.00333333333e-05" ixy="0" ixz="0" iyy="2.90666666667e-05" iyz="0" izz="1.40333333333e-05"/>
    </inertial>
    <visual>
      <origin rpy="0 -1.57  -1.55" xyz="-0.14 0.015  -0.03"/>
      <geometry>
        <mesh filename="meshes/hand/fore_middlep.stl" scale="0.001 0.001 0.001"/>
      </geometry>
      <material name="HandGray"/>
    </visual>
    <collision>
      <origin rpy="0 -1.57  -1.55" xyz="-0.14 0.015  -0.03"/>
      <geometry>
        <mesh filename="meshes/hand/fore_middlep.stl" scale="0.001 0.001 0.001"/>
      </geometry>
    </collision>
  </link>
  <gazebo reference="R_MID_link">
    <material value="Gazebo/White"/>
    <turnGravityOff>1</turnGravityOff>
  </gazebo>
  
  <joint name="R_INS" type="revolute">
    <parent link="R_palm"/>
    <child link="R_INS_link"/>
    <origin rpy="1.570796 -1.536488 1.570796" xyz="-0.002529881 0.036800135 0.108743545"/>
    <axis xyz="0 0 1"/>
    <limit effort="100" lower="-0.261" upper="0.2618" velocity="100"/>
    <dynamics damping="0.005"/>
  </joint>
  <transmission name="R_INS_trans">
    <type>transmission_interface/SimpleTransmission</type>
    <joint name="R_INS">
      <hardwareInterface>EffortJointInterface</hardwareInterface>
    </joint>
    <actuator name="R_INS_motor">
      <mechanicalReduction>1</mechanicalReduction>
    </actuator>
  </transmission>
  <link name="R_INS_link">
    <inertial>
      <origin rpy="0 0 0" xyz="0.004 0 0"/>
      <mass value="0.1"/>
      <inertia ixx="2.24083333333e-05" ixy="0" ixz="0" iyy="1.42833333333e-05" iyz="0" izz="1.85416666667e-05"/>
    </inertial>
    <visual>
      <origin rpy="0 0 0" xyz="0 0 0"/>
      <geometry>
        <mesh filename="meshes/hand/finger_base.stl"/>
      </geometry>
      <material name="HandGray"/>
    </visual>
    <collision>
      <origin rpy="0 0 0" xyz="0 0 0"/>
      <geometry>
        <mesh filename="meshes/hand/finger_base.stl"/>
      </geometry>
    </collision>
  </link>
  <gazebo reference="R_INS_link">
    <material value="Gazebo/White"/>
    <turnGravityOff>1</turnGravityOff>
  </gazebo>
  <joint name="R_INP" type="revolute">
    <parent link="R_INS_link"/>
    <child link="R_INP_link"/>
    <origin rpy="1.570796 0 0" xyz="0 0 0"/>
    <axis xyz="0 0 1"/>
    <limit effort="100" lower="0.087" upper="1.4835" velocity="100"/>
    <dynamics damping="0.005"/>
  </joint>
  <transmission name="R_INP_trans">
    <type>transmission_interface/SimpleTransmission</type>
    <joint name="R_INP">
      <hardwareInterface>EffortJointInterface</hardwareInterface>
    </joint>
    <actuator name="R_INP_motor">
      <mechanicalReduction>1</mechanicalReduction>
    </actuator>
  </transmission>
  <link name="R_INP_link">
    <inertial>
      <origin rpy="0 0 0" xyz="0.035 -0.02 0"/>
      <mass value="0.1"/>
      <inertia ixx="6.68333333333e-05" ixy="0" ixz="0" iyy="7.00416666667e-05" iyz="0" izz="2.48083333333e-05"/>
    </inertial>
    <visual>
      <origin rpy="0 -1.57  -1.57 " xyz="-0.085 0.015  -0.03"/>
      <geometry>
        <mesh filename="meshes/hand/fore_proximalp.stl" scale="0.001 0.001 0.001"/>
      </geometry>
      <material name="HandGray"/>
    </visual>
    <collision>
      <origin rpy="0 -1.57  -1.57" xyz="-0.085 0.015  -0.03"/>
      <geometry>
        <mesh filename="meshes/hand/fore_proximalp.stl" scale="0.001 0.001 0.001"/>
      </geometry>
    </collision>
  </link>
  <gazebo reference="R_INP_link">
    <material value="Gazebo/White"/>
    <turnGravityOff>1</turnGravityOff>
  </gazebo>
  <joint name="R_IND" type="revolute">
    <parent link="R_INP_link"/>
    <child link="R_IND_link"/>
    <origin rpy="0 0 0" xyz="0.055 0 0"/>
    <axis xyz="0 0 1"/>
    <limit effort="100" lower="0.087" upper="1.1345" velocity="100"/>
    <dynamics damping="0.005"/>
  </joint>
  <transmission name="R_IND_trans">
    <type>transmission_interface/SimpleTransmission</type>
    <joint name="R_IND">
      <hardwareInterface>EffortJointInterface</hardwareInterface>
    </joint>
    <actuator name="R_IND_motor">
      <mechanicalReduction>1</mechanicalReduction>
    </actuator>
  </transmission>
  <link name="R_IND_link">
    <inertial>
      <origin rpy="0 0 0" xyz="0.015 -0.01 0"/>
      <mass value="0.1"/>
      <inertia ixx="3.00333333333e-05" ixy="0" ixz="0" iyy="2.90666666667e-05" iyz="0" izz="1.40333333333e-05"/>
    </inertial>
    <visual>
      <origin rpy="0 -1.57  -1.55" xyz="-0.14 0.015  -0.03"/>
      <geometry>
        <mesh filename="meshes/hand/fore_middlep.stl" scale="0.001 0.001 0.001"/>
      </geometry>
      <material name="HandGray"/>
    </visual>
    <collision>
      <origin rpy="0 -1.57  -1.55" xyz="-0.14 0.015  -0.03"/>
      <geometry>
        <mesh filename="meshes/hand/fore_middlep.stl" scale="0.001 0.001 0.001"/>
      </geometry>
    </collision>
  </link>
  <gazebo reference="R_IND_link">
    <material value="Gazebo/White"/>
    <turnGravityOff>1</turnGravityOff>
  </gazebo>
  
  <joint name="R_THS" type="revolute">
    <parent link="R_palm"/>
    <child link="R_THS_link"/>
    <origin rpy="0.0 -0.959927 0.60796" xyz="0.062569057 0.044544548 0.080044647"/>
    <axis xyz="0 0 1"/>
    <limit effort="100" lower="-0.261" upper="0.2618" velocity="100"/>
    <dynamics damping="0.005"/>
  </joint>
  <transmission name="R_THS_trans">
    <type>transmission_interface/SimpleTransmission</type>
    <joint name="R_THS">
      <hardwareInterface>EffortJointInterface</hardwareInterface>
    </joint>
    <actuator name="R_THS_motor">
      <mechanicalReduction>1</mechanicalReduction>
    </actuator>
  </transmission>
  <link name="R_THS_link">
    <inertial>
      <origin rpy="0 0 0" xyz="0.004 0 0"/>
      <mass value="0.1"/>
      <inertia ixx="2.24083333333e-05" ixy="0" ixz="0" iyy="1.42833333333e-05" iyz="0" izz="1.85416666667e-05"/>
    </inertial>
    <visual>
      <origin rpy="0 0 0" xyz="0 0 0"/>
      <geometry>
        <mesh filename="meshes/hand/finger_base.stl"/>
      </geometry>
      <material name="HandGray"/>
    </visual>
    <collision>
      <origin rpy="0 0 0" xyz="0 0 0"/>
      <geometry>
        <mesh filename="meshes/hand/finger_base.stl"/>
      </geometry>
    </collision>
  </link>
  <gazebo reference="R_THS_link">
    <material value="Gazebo/White"/>
    <turnGravityOff>1</turnGravityOff>
  </gazebo>
  <joint name="R_THP" type="revolute">
    <parent link="R_THS_link"/>
    <child link="R_THP_link"/>
    <origin rpy="1.570796 0 0" xyz="0 0 0"/>
    <axis xyz="0 0 1"/>
    <limit effort="100" lower="0.087" upper="1.4835" velocity="100"/>
    <dynamics damping="0.005"/>
  </joint>
  <transmission name="R_THP_trans">
    <type>transmission_interface/SimpleTransmission</type>
    <joint name="R_THP">
      <hardwareInterface>EffortJointInterface</hardwareInterface>
    </joint>
    <actuator name="R_THP_motor">
      <mechanicalReduction>1</mechanicalReduction>
    </actuator>
  </transmission>
  <link name="R_THP_link">
    <inertial>
      <origin rpy="0 0 0" xyz="0.035 -0.02 0"/>
      <mass value="0.1"/>
      <inertia ixx="6.68333333333e-05" ixy="0" ixz="0" iyy="7.00416666667e-05" iyz="0" izz="2.48083333333e-05"/>
    </inertial>
    <visual>
      <origin rpy="0 -1.57  -1.57 " xyz="-0.085 0.015  -0.03"/>
      <geometry>
        <mesh filename="meshes/hand/fore_proximalp.stl" scale="0.001 0.001 0.001"/>
      </geometry>
      <material name="HandGray"/>
    </visual>
    <collision>
      <origin rpy="0 -1.57  -1.57" xyz="-0.085 0.015  -0.03"/>
      <geometry>
        <mesh filename="meshes/hand/fore_proximalp.stl" scale="0.001 0.001 0.001"/>
      </geometry>
    </collision>
  </link>
  <gazebo reference="R_THP_link">
    <material value="Gazebo/White"/>
    <turnGravityOff>1</turnGravityOff>
  </gazebo>
  <joint name="R_THD" type="revolute">
    <parent link="R_THP_link"/>
    <child link="R_THD_link"/>
    <origin rpy="0 0 0" xyz="0.055 0 0"/>
    <axis xyz="0 0 1"/>
    <limit effort="100" lower="0.087" upper="1.1345" velocity="100"/>
    <dynamics damping="0.005"/>
  </joint>
  <transmission name="R_THD_trans">
    <type>transmission_interface/SimpleTransmission</type>
    <joint name="R_THD">
      <hardwareInterface>EffortJointInterface</hardwareInterface>
    </joint>
    <actuator name="R_THD_motor">
      <mechanicalReduction>1</mechanicalReduction>
    </actuator>
  </transmission>
  <link name="R_THD_link">
    <inertial>
      <origin rpy="0 0 0" xyz="0.015 -0.01 0"/>
      <mass value="0.1"/>
      <inertia ixx="3.00333333333e-05" ixy="0" ixz="0" iyy="2.90666666667e-05" iyz="0" izz="1.40333333333e-05"/>
    </inertial>
    <visual>
      <origin rpy="0 -1.57  -1.55" xyz="-0.14 0.015  -0.03"/>
      <geometry>
        <mesh filename="meshes/hand/fore_middlep.stl" scale="0.001 0.001 0.001"/>
      </geometry>
      <material name="HandGray"/>
    </visual>
    <collision>
      <origin rpy="0 -1.57  -1.55" xyz="-0.14 0.015  -0.03"/>
      <geometry>
        <mesh filename="meshes/hand/fore_middlep.stl" scale="0.001 0.001 0.001"/>
      </geometry>
    </collision>
  </link>
  <gazebo reference="R_THD_link">
    <material value="Gazebo/White"/>
    <turnGravityOff>1</turnGravityOff>
  </gazebo>
  <!-- left Hand of darias -->
  <joint name="L_mount" type="fixed">
    <limit effort="10000.0" lower="-2.96705972839" upper="2.96705972839" velocity="3.14159265359"/>
    <parent link="left_endeffector_link"/>
    <child link="L_palm"/>
    <origin rpy="0 0 -1.57" xyz="0.0 0 0"/>
  </joint>
  <link name="L_palm">
    <inertial>
      <origin rpy="0 0 0" xyz="-0.004 0.002 0.076"/>
      <mass value="0.5"/>
      <inertia ixx="0.00141454166667" ixy="0" ixz="0" iyy="0.000900333333333" iyz="0" izz="0.00175454166667"/>
    </inertial>
    <visual>
      <origin rpy="1.57 0  1.57 " xyz="0.02 -0.007  0.025"/>
      <geometry>
        <mesh filename="meshes/hand/lefthandbase.stl"/>
      </geometry>
      <material name="HandGray"/>
    </visual>
    <collision>
      <origin rpy="1.57 0  1.57" xyz="0.02 -0.007  0.025"/>
      <geometry>
        <mesh filename="meshes/hand/lefthandbase.stl"/>
      </geometry>
    </collision>
  </link>
  <gazebo reference="L_palm">
    <material value="Gazebo/White"/>
    <turnGravityOff>1</turnGravityOff>
  </gazebo>
  <joint name="L_SMS" type="revolute">
    <parent link="L_palm"/>
    <child link="L_SMS_link"/>
    <origin rpy="1.570796 -1.536488 1.570796" xyz="0.000971571 0.043396306 0.095043545"/>
    <axis xyz="0 0 1"/>
    <limit effort="100" lower="-0.261" upper="0.2618" velocity="100"/>
    <dynamics damping="0.005"/>
  </joint>
  <transmission name="L_SMS_trans">
    <type>transmission_interface/SimpleTransmission</type>
    <joint name="L_SMS">
      <hardwareInterface>EffortJointInterface</hardwareInterface>
    </joint>  
    <actuator name="L_SMS_motor">
      <mechanicalReduction>1</mechanicalReduction>
    </actuator>
  </transmission>
  <link name="L_SMS_link">
    <inertial>
      <origin rpy="0 0 0" xyz="0.004 0 0"/>
      <mass value="0.1"/>
      <inertia ixx="2.24083333333e-05" ixy="0" ixz="0" iyy="1.42833333333e-05" iyz="0" izz="1.85416666667e-05"/>
    </inertial>
    <visual>
      <origin rpy="0 0 0" xyz="0 0 0"/>
      <geometry>
        <mesh filename="meshes/hand/finger_base.stl"/>
      </geometry>
      <material name="HandGray"/>
    </visual>
    <collision>
      <origin rpy="0 0 0" xyz="0 0 0"/>
      <geometry>
        <mesh filename="meshes/hand/finger_base.stl"/>
      </geometry>
    </collision>
  </link>
  <gazebo reference="L_SMS_link">
    <material value="Gazebo/White"/>
    <turnGravityOff>1</turnGravityOff>
  </gazebo>
  <joint name="L_SMP" type="revolute">
    <parent link="L_SMS_link"/>
    <child link="L_SMP_link"/>
    <origin rpy="1.570796 0 0" xyz="0 0 0"/>
    <axis xyz="0 0 1"/>
    <limit effort="100" lower="0.087" upper="1.4835" velocity="100"/>
    <dynamics damping="0.005"/>
  </joint>
  <transmission name="L_SMP_trans">
    <type>transmission_interface/SimpleTransmission</type>
    <joint name="L_SMP">
      <hardwareInterface>EffortJointInterface</hardwareInterface>
    </joint>
    <actuator name="L_SMP_motor">
      <mechanicalReduction>1</mechanicalReduction>
    </actuator>
  </transmission>
  <link name="L_SMP_link">
    <inertial>
      <origin rpy="0 0 0" xyz="0.035 -0.02 0"/>
      <mass value="0.1"/>
      <inertia ixx="6.68333333333e-05" ixy="0" ixz="0" iyy="7.00416666667e-05" iyz="0" izz="2.48083333333e-05"/>
    </inertial>
    <visual>
      <origin rpy="0 -1.57  -1.57 " xyz="-0.085 0.015  -0.03"/>
      <geometry>
        <mesh filename="meshes/hand/fore_proximalp.stl" scale="0.001 0.001 0.001"/>
      </geometry>
      <material name="HandGray"/>
    </visual>
    <collision>
      <origin rpy="0 -1.57  -1.57" xyz="-0.085 0.015  -0.03"/>
      <geometry>
        <mesh filename="meshes/hand/fore_proximalp.stl" scale="0.001 0.001 0.001"/>
      </geometry>
    </collision>
  </link>
  <gazebo reference="L_SMP_link">
    <material value="Gazebo/White"/>
    <turnGravityOff>1</turnGravityOff>
  </gazebo>
  <joint name="L_SMD" type="revolute">
    <parent link="L_SMP_link"/>
    <child link="L_SMD_link"/>
    <origin rpy="0 0 0" xyz="0.055 0 0"/>
    <axis xyz="0 0 1"/>
    <limit effort="100" lower="0.087" upper="1.1345" velocity="100"/>
    <dynamics damping="0.005"/>
  </joint>
  <transmission name="L_SMD_trans">
    <type>transmission_interface/SimpleTransmission</type>
    <joint name="L_SMD">
      <hardwareInterface>EffortJointInterface</hardwareInterface>
    </joint>
    <actuator name="L_SMD_motor">
      <mechanicalReduction>1</mechanicalReduction>
    </actuator>
  </transmission>
  <link name="L_SMD_link">
    <inertial>
      <origin rpy="0 0 0" xyz="0.015 -0.01 0"/>
      <mass value="0.1"/>
      <inertia ixx="3.00333333333e-05" ixy="0" ixz="0" iyy="2.90666666667e-05" iyz="0" izz="1.40333333333e-05"/>
    </inertial>
    <visual>
      <origin rpy="0 -1.57  -1.55" xyz="-0.14 0.015  -0.03"/>
      <geometry>
        <mesh filename="meshes/hand/fore_middlep.stl" scale="0.001 0.001 0.001"/>
      </geometry>
      <material name="HandGray"/>
    </visual>
    <collision>
      <origin rpy="0 -1.57  -1.55" xyz="-0.14 0.015  -0.03"/>
      <geometry>
        <mesh filename="meshes/hand/fore_middlep.stl" scale="0.001 0.001 0.001"/>
      </geometry>
    </collision>
  </link>
  <gazebo reference="L_SMD_link">
    <material value="Gazebo/White"/>
    <turnGravityOff>1</turnGravityOff>
  </gazebo>
 
  <joint name="L_RIS" type="revolute">
    <parent link="L_palm"/>
    <child link="L_RIS_link"/>
    <origin rpy="1.570796 -1.536488 1.570796" xyz="-0.002529881 0.016800135 0.114043545"/>
    <axis xyz="0 0 1"/>
    <limit effort="100" lower="-0.261" upper="0.2618" velocity="100"/>
    <dynamics damping="0.005"/>
  </joint>
  <transmission name="L_RIS_trans">
    <type>transmission_interface/SimpleTransmission</type>
    <joint name="L_RIS">
      <hardwareInterface>EffortJointInterface</hardwareInterface>
    </joint>
    <actuator name="L_RIS_motor">
      <mechanicalReduction>1</mechanicalReduction>
    </actuator>
  </transmission>
  <link name="L_RIS_link">
    <inertial>
      <origin rpy="0 0 0" xyz="0.004 0 0"/>
      <mass value="0.1"/>
      <inertia ixx="2.24083333333e-05" ixy="0" ixz="0" iyy="1.42833333333e-05" iyz="0" izz="1.85416666667e-05"/>
    </inertial>
    <visual>
      <origin rpy="0 0 0" xyz="0 0 0"/>
      <geometry>
        <mesh filename="meshes/hand/finger_base.stl"/>
      </geometry>
      <material name="HandGray"/>
    </visual>
    <collision>
      <origin rpy="0 0 0" xyz="0 0 0"/>
      <geometry>
        <mesh filename="meshes/hand/finger_base.stl"/>
      </geometry>
    </collision>
  </link>
  <gazebo reference="L_RIS_link">
    <material value="Gazebo/White"/>
    <turnGravityOff>1</turnGravityOff>
  </gazebo>
  <joint name="L_RIP" type="revolute">
    <parent link="L_RIS_link"/>
    <child link="L_RIP_link"/>
    <origin rpy="1.570796 0 0" xyz="0 0 0"/>
    <axis xyz="0 0 1"/>
    <limit effort="100" lower="0.087" upper="1.4835" velocity="100"/>
    <dynamics damping="0.005"/>
  </joint>
  <transmission name="L_RIP_trans">
    <type>transmission_interface/SimpleTransmission</type>
    <joint name="L_RIP">
      <hardwareInterface>EffortJointInterface</hardwareInterface>
    </joint>
    <actuator name="L_RIP_motor">
      <mechanicalReduction>1</mechanicalReduction>
    </actuator>
  </transmission>
  <link name="L_RIP_link">
    <inertial>
      <origin rpy="0 0 0" xyz="0.035 -0.02 0"/>
      <mass value="0.1"/>
      <inertia ixx="6.68333333333e-05" ixy="0" ixz="0" iyy="7.00416666667e-05" iyz="0" izz="2.48083333333e-05"/>
    </inertial>
    <visual>
      <origin rpy="0 -1.57  -1.57 " xyz="-0.085 0.015  -0.03"/>
      <geometry>
        <mesh filename="meshes/hand/fore_proximalp.stl" scale="0.001 0.001 0.001"/>
      </geometry>
      <material name="HandGray"/>
    </visual>
    <collision>
      <origin rpy="0 -1.57  -1.57" xyz="-0.085 0.015  -0.03"/>
      <geometry>
        <mesh filename="meshes/hand/fore_proximalp.stl" scale="0.001 0.001 0.001"/>
      </geometry>
    </collision>
  </link>
  <gazebo reference="L_RIP_link">
    <material value="Gazebo/White"/>
    <turnGravityOff>1</turnGravityOff>
  </gazebo>
  <joint name="L_RID" type="revolute">
    <parent link="L_RIP_link"/>
    <child link="L_RID_link"/>
    <origin rpy="0 0 0" xyz="0.055 0 0"/>
    <axis xyz="0 0 1"/>
    <limit effort="100" lower="0.087" upper="1.1345" velocity="100"/>
    <dynamics damping="0.005"/>
  </joint>
  <transmission name="L_RID_trans">
    <type>transmission_interface/SimpleTransmission</type>
    <joint name="L_RID">
      <hardwareInterface>EffortJointInterface</hardwareInterface>
    </joint>
    <actuator name="L_RID_motor">
      <mechanicalReduction>1</mechanicalReduction>
    </actuator>
  </transmission>
  <link name="L_RID_link">
    <inertial>
      <origin rpy="0 0 0" xyz="0.015 -0.01 0"/>
      <mass value="0.1"/>
      <inertia ixx="3.00333333333e-05" ixy="0" ixz="0" iyy="2.90666666667e-05" iyz="0" izz="1.40333333333e-05"/>
    </inertial>
    <visual>
      <origin rpy="0 -1.57  -1.55" xyz="-0.14 0.015  -0.03"/>
      <geometry>
        <mesh filename="meshes/hand/fore_middlep.stl" scale="0.001 0.001 0.001"/>
      </geometry>
      <material name="HandGray"/>
    </visual>
    <collision>
      <origin rpy="0 -1.57  -1.55" xyz="-0.14 0.015  -0.03"/>
      <geometry>
        <mesh filename="meshes/hand/fore_middlep.stl" scale="0.001 0.001 0.001"/>
      </geometry>
    </collision>
  </link>
  <gazebo reference="L_RID_link">
    <material value="Gazebo/White"/>
    <turnGravityOff>1</turnGravityOff>
  </gazebo>
  
  <joint name="L_MIS" type="revolute">
    <parent link="L_palm"/>
    <child link="L_MIS_link"/>
    <origin rpy="1.570796 -1.536488 1.570796" xyz=" -0.0037 -0.01 0.1190 "/>
    <axis xyz="0 0 1"/>
    <limit effort="100" lower="-0.261" upper="0.2618" velocity="100"/>
    <dynamics damping="0.005"/>
  </joint>
  <transmission name="L_MIS_trans">
    <type>transmission_interface/SimpleTransmission</type>
    <joint name="L_MIS">
      <hardwareInterface>EffortJointInterface</hardwareInterface>
    </joint>
    <actuator name="L_MIS_motor">
      <mechanicalReduction>1</mechanicalReduction>
    </actuator>
  </transmission>
  <link name="L_MIS_link">
    <inertial>
      <origin rpy="0 0 0" xyz="0.004 0 0"/>
      <mass value="0.1"/>
      <inertia ixx="2.24083333333e-05" ixy="0" ixz="0" iyy="1.42833333333e-05" iyz="0" izz="1.85416666667e-05"/>
    </inertial>
    <visual>
      <origin rpy="0 0 0" xyz="0 0 0"/>
      <geometry>
        <mesh filename="meshes/hand/finger_base.stl"/>
      </geometry>
      <material name="HandGray"/>
    </visual>
    <collision>
      <origin rpy="0 0 0" xyz="0 0 0"/>
      <geometry>
        <mesh filename="meshes/hand/finger_base.stl"/>
      </geometry>
    </collision>
  </link>
  <gazebo reference="L_MIS_link">
    <material value="Gazebo/White"/>
    <turnGravityOff>1</turnGravityOff>
  </gazebo>
  <joint name="L_MIP" type="revolute">
    <parent link="L_MIS_link"/>
    <child link="L_MIP_link"/>
    <origin rpy="1.570796 0 0" xyz="0 0 0"/>
    <axis xyz="0 0 1"/>
    <limit effort="100" lower="0.087" upper="1.4835" velocity="100"/>
    <dynamics damping="0.005"/>
  </joint>
  <transmission name="L_MIP_trans">
    <type>transmission_interface/SimpleTransmission</type>
    <joint name="L_MIP">
      <hardwareInterface>EffortJointInterface</hardwareInterface>
    </joint>
    <actuator name="L_MIP_motor">
      <mechanicalReduction>1</mechanicalReduction>
    </actuator>
  </transmission>
  <link name="L_MIP_link">
    <inertial>
      <origin rpy="0 0 0" xyz="0.035 -0.02 0"/>
      <mass value="0.1"/>
      <inertia ixx="6.68333333333e-05" ixy="0" ixz="0" iyy="7.00416666667e-05" iyz="0" izz="2.48083333333e-05"/>
    </inertial>
    <visual>
      <origin rpy="0 -1.57  -1.57 " xyz="-0.085 0.015  -0.03"/>
      <geometry>
        <mesh filename="meshes/hand/fore_proximalp.stl" scale="0.001 0.001 0.001"/>
      </geometry>
      <material name="HandGray"/>
    </visual>
    <collision>
      <origin rpy="0 -1.57  -1.57" xyz="-0.085 0.015  -0.03"/>
      <geometry>
        <mesh filename="meshes/hand/fore_proximalp.stl" scale="0.001 0.001 0.001"/>
      </geometry>
    </collision>
  </link>
  <gazebo reference="L_MIP_link">
    <material value="Gazebo/White"/>
    <turnGravityOff>1</turnGravityOff>
  </gazebo>
  <joint name="L_MID" type="revolute">
    <parent link="L_MIP_link"/>
    <child link="L_MID_link"/>
    <origin rpy="0 0 0" xyz="0.055 0 0"/>
    <axis xyz="0 0 1"/>
    <limit effort="100" lower="0.087" upper="1.1345" velocity="100"/>
    <dynamics damping="0.005"/>
  </joint>
  <transmission name="L_MID_trans">
    <type>transmission_interface/SimpleTransmission</type>
    <joint name="L_MID">
      <hardwareInterface>EffortJointInterface</hardwareInterface>
    </joint>
    <actuator name="L_MID_motor">
      <mechanicalReduction>1</mechanicalReduction>
    </actuator>
  </transmission>
  <link name="L_MID_link">
    <inertial>
      <origin rpy="0 0 0" xyz="0.015 -0.01 0"/>
      <mass value="0.1"/>
      <inertia ixx="3.00333333333e-05" ixy="0" ixz="0" iyy="2.90666666667e-05" iyz="0" izz="1.40333333333e-05"/>
    </inertial>
    <visual>
      <origin rpy="0 -1.57  -1.55" xyz="-0.14 0.015  -0.03"/>
      <geometry>
        <mesh filename="meshes/hand/fore_middlep.stl" scale="0.001 0.001 0.001"/>
      </geometry>
      <material name="HandGray"/>
    </visual>
    <collision>
      <origin rpy="0 -1.57  -1.55" xyz="-0.14 0.015  -0.03"/>
      <geometry>
        <mesh filename="meshes/hand/fore_middlep.stl" scale="0.001 0.001 0.001"/>
      </geometry>
    </collision>
  </link>
  <gazebo reference="L_MID_link">
    <material value="Gazebo/White"/>
    <turnGravityOff>1</turnGravityOff>
  </gazebo>
  
  <joint name="L_INS" type="revolute">
    <parent link="L_palm"/>
    <child link="L_INS_link"/>
    <origin rpy="1.570796 -1.536488 1.570796" xyz=" -0.002529881 -0.036800135 0.108743545"/>
    <axis xyz="0 0 1"/>
    <limit effort="100" lower="-0.261" upper="0.2618" velocity="100"/>
    <dynamics damping="0.005"/>
  </joint>
  <transmission name="L_INS_trans">
    <type>transmission_interface/SimpleTransmission</type>
    <joint name="L_INS">
      <hardwareInterface>EffortJointInterface</hardwareInterface>
    </joint>
    <actuator name="L_INS_motor">
      <mechanicalReduction>1</mechanicalReduction>
    </actuator>
  </transmission>
  <link name="L_INS_link">
    <inertial>
      <origin rpy="0 0 0" xyz="0.004 0 0"/>
      <mass value="0.1"/>
      <inertia ixx="2.24083333333e-05" ixy="0" ixz="0" iyy="1.42833333333e-05" iyz="0" izz="1.85416666667e-05"/>
    </inertial>
    <visual>
      <origin rpy="0 0 0" xyz="0 0 0"/>
      <geometry>
        <mesh filename="meshes/hand/finger_base.stl"/>
      </geometry>
      <material name="HandGray"/>
    </visual>
    <collision>
      <origin rpy="0 0 0" xyz="0 0 0"/>
      <geometry>
        <mesh filename="meshes/hand/finger_base.stl"/>
      </geometry>
    </collision>
  </link>
  <gazebo reference="L_INS_link">
    <material value="Gazebo/White"/>
    <turnGravityOff>1</turnGravityOff>
  </gazebo>
  <joint name="L_INP" type="revolute">
    <parent link="L_INS_link"/>
    <child link="L_INP_link"/>
    <origin rpy="1.570796 0 0" xyz="0 0 0"/>
    <axis xyz="0 0 1"/>
    <limit effort="100" lower="0.087" upper="1.4835" velocity="100"/>
    <dynamics damping="0.005"/>
  </joint>
  <transmission name="L_INP_trans">
    <type>transmission_interface/SimpleTransmission</type>
    <joint name="L_INP">
      <hardwareInterface>EffortJointInterface</hardwareInterface>
    </joint>
    <actuator name="L_INP_motor">
      <mechanicalReduction>1</mechanicalReduction>
    </actuator>
  </transmission>
  <link name="L_INP_link">
    <inertial>
      <origin rpy="0 0 0" xyz="0.035 -0.02 0"/>
      <mass value="0.1"/>
      <inertia ixx="6.68333333333e-05" ixy="0" ixz="0" iyy="7.00416666667e-05" iyz="0" izz="2.48083333333e-05"/>
    </inertial>
    <visual>
      <origin rpy="0 -1.57  -1.57 " xyz="-0.085 0.015  -0.03"/>
      <geometry>
        <mesh filename="package://meshes/hand/fore_proximalp.stl" scale="0.001 0.001 0.001"/>
      </geometry>
      <material name="HandGray"/>
    </visual>
    <collision>
      <origin rpy="0 -1.57  -1.57" xyz="-0.085 0.015  -0.03"/>
      <geometry>
        <mesh filename="package://meshes/hand/fore_proximalp.stl" scale="0.001 0.001 0.001"/>
      </geometry>
    </collision>
  </link>
  <gazebo reference="L_INP_link">
    <material value="Gazebo/White"/>
    <turnGravityOff>1</turnGravityOff>
  </gazebo>
  <joint name="L_IND" type="revolute">
    <parent link="L_INP_link"/>
    <child link="L_IND_link"/>
    <origin rpy="0 0 0" xyz="0.055 0 0"/>
    <axis xyz="0 0 1"/>
    <limit effort="100" lower="0.087" upper="1.1345" velocity="100"/>
    <dynamics damping="0.005"/>
  </joint>
  <transmission name="L_IND_trans">
    <type>transmission_interface/SimpleTransmission</type>
    <joint name="L_IND">
      <hardwareInterface>EffortJointInterface</hardwareInterface>
    </joint>
    <actuator name="L_IND_motor">
      <mechanicalReduction>1</mechanicalReduction>
    </actuator>
  </transmission>
  <link name="L_IND_link">
    <inertial>
      <origin rpy="0 0 0" xyz="0.015 -0.01 0"/>
      <mass value="0.1"/>
      <inertia ixx="3.00333333333e-05" ixy="0" ixz="0" iyy="2.90666666667e-05" iyz="0" izz="1.40333333333e-05"/>
    </inertial>
    <visual>
      <origin rpy="0 -1.57  -1.55" xyz="-0.14 0.015  -0.03"/>
      <geometry>
        <mesh filename="package://meshes/hand/fore_middlep.stl" scale="0.001 0.001 0.001"/>
      </geometry>
      <material name="HandGray"/>
    </visual>
    <collision>
      <origin rpy="0 -1.57  -1.55" xyz="-0.14 0.015  -0.03"/>
      <geometry>
        <mesh filename="package://meshes/hand/fore_middlep.stl" scale="0.001 0.001 0.001"/>
      </geometry>
    </collision>
  </link>
  <gazebo reference="L_IND_link">
    <material value="Gazebo/White"/>
    <turnGravityOff>1</turnGravityOff>
  </gazebo>

  <joint name="L_THS" type="revolute">
    <parent link="L_palm"/>
    <child link="L_THS_link"/>
    <origin rpy="0.0 -0.959927 -0.60796" xyz="0.062569057 -0.044544548 0.080044647"/>
    <axis xyz="0 0 1"/>
    <limit effort="100" lower="-0.261" upper="0.2618" velocity="100"/>
    <dynamics damping="0.005"/>
  </joint>
  <transmission name="L_THS_trans">
    <type>transmission_interface/SimpleTransmission</type>
    <joint name="L_THS">
      <hardwareInterface>EffortJointInterface</hardwareInterface>
    </joint>
    <actuator name="L_THS_motor">
      <mechanicalReduction>1</mechanicalReduction>
    </actuator>
  </transmission>
  <link name="L_THS_link">
    <inertial>
      <origin rpy="0 0 0" xyz="0.004 0 0"/>
      <mass value="0.1"/>
      <inertia ixx="2.24083333333e-05" ixy="0" ixz="0" iyy="1.42833333333e-05" iyz="0" izz="1.85416666667e-05"/>
    </inertial>
    <visual>
      <origin rpy="0 0 0" xyz="0 0 0"/>
      <geometry>
        <mesh filename="package://meshes/hand/finger_base.stl"/>
      </geometry>
      <material name="HandGray"/>
    </visual>
    <collision>
      <origin rpy="0 0 0" xyz="0 0 0"/>
      <geometry>
        <mesh filename="meshes/hand/finger_base.stl"/>
      </geometry>
    </collision>
  </link>
  <gazebo reference="L_THS_link">
    <material value="Gazebo/White"/>
    <turnGravityOff>1</turnGravityOff>
  </gazebo>
  <joint name="L_THP" type="revolute">
    <parent link="L_THS_link"/>
    <child link="L_THP_link"/>
    <origin rpy="1.570796 0 0" xyz="0 0 0"/>
    <axis xyz="0 0 1"/>
    <limit effort="100" lower="0.087" upper="1.4835" velocity="100"/>
    <dynamics damping="0.005"/>
  </joint>
  <transmission name="L_THP_trans">
    <type>transmission_interface/SimpleTransmission</type>
    <joint name="L_THP">
      <hardwareInterface>EffortJointInterface</hardwareInterface>
    </joint>
    <actuator name="L_THP_motor">
      <mechanicalReduction>1</mechanicalReduction>
    </actuator>
  </transmission>
  <link name="L_THP_link">
    <inertial>
      <origin rpy="0 0 0" xyz="0.035 -0.02 0"/>
      <mass value="0.1"/>
      <inertia ixx="6.68333333333e-05" ixy="0" ixz="0" iyy="7.00416666667e-05" iyz="0" izz="2.48083333333e-05"/>
    </inertial>
    <visual>
      <origin rpy="0 -1.57  -1.57 " xyz="-0.085 0.015  -0.03"/>
      <geometry>
        <mesh filename="meshes/hand/fore_proximalp.stl" scale="0.001 0.001 0.001"/>
      </geometry>
      <material name="HandGray"/>
    </visual>
    <collision>
      <origin rpy="0 -1.57  -1.57" xyz="-0.085 0.015  -0.03"/>
      <geometry>
        <mesh filename="meshes/hand/fore_proximalp.stl" scale="0.001 0.001 0.001"/>
      </geometry>
    </collision>
  </link>
  <gazebo reference="L_THP_link">
    <material value="Gazebo/White"/>
    <turnGravityOff>1</turnGravityOff>
  </gazebo>
  <joint name="L_THD" type="revolute">
    <parent link="L_THP_link"/>
    <child link="L_THD_link"/>
    <origin rpy="0 0 0" xyz="0.055 0 0"/>
    <axis xyz="0 0 1"/>
    <limit effort="100" lower="0.087" upper="1.1345" velocity="100"/>
    <dynamics damping="0.005"/>
  </joint>
  <transmission name="L_THD_trans">
    <type>transmission_interface/SimpleTransmission</type>
    <joint name="L_THD">
      <hardwareInterface>EffortJointInterface</hardwareInterface>
    </joint>
    <actuator name="L_THD_motor">
      <mechanicalReduction>1</mechanicalReduction>
    </actuator>
  </transmission>
  <link name="L_THD_link">
    <inertial>
      <origin rpy="0 0 0" xyz="0.015 -0.01 0"/>
      <mass value="0.1"/>
      <inertia ixx="3.00333333333e-05" ixy="0" ixz="0" iyy="2.90666666667e-05" iyz="0" izz="1.40333333333e-05"/>
    </inertial>
    <visual>
      <origin rpy="0 -1.57  -1.55" xyz="-0.14 0.015  -0.03"/>
      <geometry>
        <mesh filename="meshes/hand/fore_middlep.stl" scale="0.001 0.001 0.001"/>
      </geometry>
      <material name="HandGray"/>
    </visual>
    <collision>
      <origin rpy="0 -1.57  -1.55" xyz="-0.14 0.015  -0.03"/>
      <geometry>
        <mesh filename="meshes/hand/fore_middlep.stl" scale="0.001 0.001 0.001"/>
      </geometry>
    </collision>
  </link>
  <gazebo reference="L_THD_link">
    <material value="Gazebo/White"/>
    <turnGravityOff>1</turnGravityOff>
  </gazebo>
  
  <!-- gazebo plugin for ros control -->
  <gazebo>
    <plugin filename="libgazebo_ros_control.so" name="gazebo_ros_control">
      <robotNamespace>/darias</robotNamespace>
    </plugin>
  </gazebo>
</robot>
