<?xml version="1.0" ?>
<!-- =================================================================================== -->
<!-- |    This document was autogenerated by xacro from hexapod.urdf.xacro             | -->
<!-- |    EDITING THIS FILE BY HAND IS NOT RECOMMENDED                                 | -->
<!-- =================================================================================== -->
<robot name="iiwa">
  <link name="hexapod/base_link"/>
  <link name="hexapod/body">
    <visual>
      <origin rpy="0 0 0" xyz="0 0 0"/>
      <geometry>
        <mesh filename="meshes/visual/base.stl"/>
      </geometry>
    </visual>
    <collision>
      <origin rpy="0 0 0" xyz="0 0 0"/>
      <geometry>
        <mesh filename="meshes/collision/base.stl"/>
      </geometry>
    </collision>
    <inertial>
      <mass value="0.53699"/>
      <origin rpy="0 0 0" xyz="0.00372 0 0.001"/>
      <inertia ixx="0.01109" ixy="0" ixz="0" iyy="0.00244" iyz="0" izz="0.00355"/>
    </inertial>
  </link>
  <joint name="hexapod/base_joint" type="fixed">
    <parent link="hexapod/base_link"/>
    <child link="hexapod/body"/>
  </joint>
  <link name="hexapod/leg_0/motor_0">
    <visual>
      <origin rpy="0 0 0" xyz="0 0 0"/>
      <geometry>
        <mesh filename="meshes/visual/motor.stl"/>
      </geometry>
    </visual>
    <collision>
      <origin rpy="0 0 0" xyz="0 0 0"/>
      <geometry>
        <mesh filename="meshes/collision/motor.stl"/>
      </geometry>
    </collision>
    <inertial>
      <mass value="0.056"/>
      <origin rpy="0 0 0" xyz="8.6786e-5 0 -0.007678"/>
      <inertia ixx="1e-3" ixy="0" ixz="0" iyy="1e-3" iyz="0" izz="1e-3"/>
    </inertial>
  </link>
  <joint name="hexapod/leg_0_motor_0_joint" type="fixed">
    <parent link="hexapod/body"/>
    <child link="hexapod/leg_0/motor_0"/>
    <origin rpy="3.141592653589793 0 1.5707963267948966" xyz="0.080 0.043 0.005"/>
  </joint>
  <link name="hexapod/leg_1/motor_0">
    <visual>
      <origin rpy="0 0 0" xyz="0 0 0"/>
      <geometry>
        <mesh filename="meshes/visual/motor.stl"/>
      </geometry>
    </visual>
    <collision>
      <origin rpy="0 0 0" xyz="0 0 0"/>
      <geometry>
        <mesh filename="meshes/collision/motor.stl"/>
      </geometry>
    </collision>
    <inertial>
      <mass value="0.056"/>
      <origin rpy="0 0 0" xyz="8.6786e-5 0 -0.007678"/>
      <inertia ixx="1e-3" ixy="0" ixz="0" iyy="1e-3" iyz="0" izz="1e-3"/>
    </inertial>
  </link>
  <joint name="hexapod/leg_1_motor_0_joint" type="fixed">
    <parent link="hexapod/body"/>
    <child link="hexapod/leg_1/motor_0"/>
    <origin rpy="3.141592653589793 0 -1.5707963267948966" xyz="0.080 -0.043 0.005"/>
  </joint>
  <link name="hexapod/leg_2/motor_0">
    <visual>
      <origin rpy="0 0 0" xyz="0 0 0"/>
      <geometry>
        <mesh filename="meshes/visual/motor.stl"/>
      </geometry>
    </visual>
    <collision>
      <origin rpy="0 0 0" xyz="0 0 0"/>
      <geometry>
        <mesh filename="meshes/collision/motor.stl"/>
      </geometry>
    </collision>
    <inertial>
      <mass value="0.056"/>
      <origin rpy="0 0 0" xyz="8.6786e-5 0 -0.007678"/>
      <inertia ixx="1e-3" ixy="0" ixz="0" iyy="1e-3" iyz="0" izz="1e-3"/>
    </inertial>
  </link>
  <joint name="hexapod/leg_2_motor_0_joint" type="fixed">
    <parent link="hexapod/body"/>
    <child link="hexapod/leg_2/motor_0"/>
    <origin rpy="3.141592653589793 0 1.5707963267948966" xyz="0.0 0.060 0.005"/>
  </joint>
  <link name="hexapod/leg_3/motor_0">
    <visual>
      <origin rpy="0 0 0" xyz="0 0 0"/>
      <geometry>
        <mesh filename="meshes/visual/motor.stl"/>
      </geometry>
    </visual>
    <collision>
      <origin rpy="0 0 0" xyz="0 0 0"/>
      <geometry>
        <mesh filename="meshes/collision/motor.stl"/>
      </geometry>
    </collision>
    <inertial>
      <mass value="0.056"/>
      <origin rpy="0 0 0" xyz="8.6786e-5 0 -0.007678"/>
      <inertia ixx="1e-3" ixy="0" ixz="0" iyy="1e-3" iyz="0" izz="1e-3"/>
    </inertial>
  </link>
  <joint name="hexapod/leg_3_motor_0_joint" type="fixed">
    <parent link="hexapod/body"/>
    <child link="hexapod/leg_3/motor_0"/>
    <origin rpy="3.141592653589793 0 -1.5707963267948966" xyz="0.0 -0.060 0.005"/>
  </joint>
  <link name="hexapod/leg_4/motor_0">
    <visual>
      <origin rpy="0 0 0" xyz="0 0 0"/>
      <geometry>
        <mesh filename="meshes/visual/motor.stl"/>
      </geometry>
    </visual>
    <collision>
      <origin rpy="0 0 0" xyz="0 0 0"/>
      <geometry>
        <mesh filename="meshes/collision/motor.stl"/>
      </geometry>
    </collision>
    <inertial>
      <mass value="0.056"/>
      <origin rpy="0 0 0" xyz="8.6786e-5 0 -0.007678"/>
      <inertia ixx="1e-3" ixy="0" ixz="0" iyy="1e-3" iyz="0" izz="1e-3"/>
    </inertial>
  </link>
  <joint name="hexapod/leg_4_motor_0_joint" type="fixed">
    <parent link="hexapod/body"/>
    <child link="hexapod/leg_4/motor_0"/>
    <origin rpy="3.141592653589793 0 1.5707963267948966" xyz="-0.080 0.043 0.005"/>
  </joint>
  <link name="hexapod/leg_5/motor_0">
    <visual>
      <origin rpy="0 0 0" xyz="0 0 0"/>
      <geometry>
        <mesh filename="meshes/visual/motor.stl"/>
      </geometry>
    </visual>
    <collision>
      <origin rpy="0 0 0" xyz="0 0 0"/>
      <geometry>
        <mesh filename="meshes/collision/motor.stl"/>
      </geometry>
    </collision>
    <inertial>
      <mass value="0.056"/>
      <origin rpy="0 0 0" xyz="8.6786e-5 0 -0.007678"/>
      <inertia ixx="1e-3" ixy="0" ixz="0" iyy="1e-3" iyz="0" izz="1e-3"/>
    </inertial>
  </link>
  <joint name="hexapod/leg_5_motor_0_joint" type="fixed">
    <parent link="hexapod/body"/>
    <child link="hexapod/leg_5/motor_0"/>
    <origin rpy="3.141592653589793 0 -1.5707963267948966" xyz="-0.080 -0.043 0.005"/>
  </joint>
  <joint name="hexapod/leg_0/joint_0" type="revolute">
    <parent link="hexapod/body"/>
    <child link="hexapod/leg_0/link_0"/>
    <origin rpy="0 0 1.5707963267948966" xyz="0.080 0.058 -0.014"/>
    <axis xyz="0 0 1"/>
    <limit effort="100" lower="-2.356194490192345" upper="2.356194490192345" velocity="1.7453292519943295"/>
  </joint>
  <link name="hexapod/leg_0/link_0">
    <visual>
      <origin rpy="0 0 0" xyz="0 0 0"/>
      <geometry>
        <mesh filename="meshes/visual/leg_0_left.stl"/>
      </geometry>
    </visual>
    <collision>
      <origin rpy="0 0 0" xyz="0 0 0"/>
      <geometry>
        <mesh filename="meshes/collision/leg_0_left.stl"/>
      </geometry>
    </collision>
    <inertial>
      <mass value="0.042061"/>
      <origin rpy="0 0 0" xyz="0.037232 0.010178 -0.005231"/>
      <!--<inertia ixx="6.67e-06" ixy="-1.158e-06" ixz="1.13e-06" iyy="2.753e-05" 
					iyz="1.78e-06" izz="2.86e-05" /> </inertial> -->
      <inertia ixx="1e-2" ixy="0.0" ixz="0.0" iyy="1e-2" iyz="0.0" izz="1e-2"/>
    </inertial>
  </link>
  <link name="hexapod/leg_0/motor_1">
    <visual>
      <origin rpy="0 0 0" xyz="0 0 0"/>
      <geometry>
        <mesh filename="meshes/visual/motor.stl"/>
      </geometry>
    </visual>
    <collision>
      <origin rpy="0 0 0" xyz="0 0 0"/>
      <geometry>
        <mesh filename="meshes/collision/motor.stl"/>
      </geometry>
    </collision>
    <inertial>
      <mass value="0.056"/>
      <origin rpy="0 0 0" xyz="8.6786e-5 0 -0.007678"/>
      <inertia ixx="1e-3" ixy="0" ixz="0" iyy="1e-3" iyz="0" izz="1e-3"/>
    </inertial>
  </link>
  <joint name="hexapod/leg_0_motor_1_joint" type="fixed">
    <parent link="hexapod/leg_0/link_0"/>
    <child link="hexapod/leg_0/motor_1"/>
    <origin rpy="1.5707963267948966 0 0" xyz="0.0465 -0.01225 -0.0145"/>
  </joint>
  <joint name="hexapod/leg_0/joint_1" type="revolute">
    <parent link="hexapod/leg_0/link_0"/>
    <child link="hexapod/leg_0/link_1"/>
    <origin rpy="1.5707963267948966 0 0" xyz="0.062 -0.032 -0.01375"/>
    <axis xyz="0 0 1"/>
    <limit effort="100" lower="-2.356194490192345" upper="2.356194490192345" velocity="1.7453292519943295"/>
  </joint>
  <link name="hexapod/leg_0/link_1">
    <visual>
      <origin rpy="0 0 0" xyz="0 0 0"/>
      <geometry>
        <mesh filename="meshes/visual/leg_1.stl"/>
      </geometry>
    </visual>
    <collision>
      <origin rpy="0 0 0" xyz="0 0 0"/>
      <geometry>
        <mesh filename="meshes/collision/leg_1.stl"/>
      </geometry>
    </collision>
    <inertial>
      <mass value="0.03207"/>
      <origin rpy="0 0 0" xyz="0.06009 0 0.00075"/>
      <!-- <inertia ixx="3.44e-06" ixy="0." ixz="0." iyy="6.75e-05" iyz="0." 
					izz="7.091e-05" /> </inertial> -->
      <inertia ixx="1e-2" ixy="0.0" ixz="0.0" iyy="1e-2" iyz="0.0" izz="1e-2"/>
    </inertial>
  </link>
  <link name="hexapod/leg_0/motor_2">
    <visual>
      <origin rpy="0 0 0" xyz="0 0 0"/>
      <geometry>
        <mesh filename="meshes/visual/motor.stl"/>
      </geometry>
    </visual>
    <collision>
      <origin rpy="0 0 0" xyz="0 0 0"/>
      <geometry>
        <mesh filename="meshes/collision/motor.stl"/>
      </geometry>
    </collision>
    <inertial>
      <mass value="0.056"/>
      <origin rpy="0 0 0" xyz="8.6786e-5 0 -0.007678"/>
      <inertia ixx="1e-3" ixy="0" ixz="0" iyy="1e-3" iyz="0" izz="1e-3"/>
    </inertial>
  </link>
  <joint name="hexapod/leg_0_motor_2_joint" type="fixed">
    <parent link="hexapod/leg_0/link_1"/>
    <child link="hexapod/leg_0/motor_2"/>
    <origin rpy="0 0 0" xyz="0.1165 0 -0.0032"/>
  </joint>
  <joint name="hexapod/leg_0/joint_2" type="revolute">
    <parent link="hexapod/leg_0/link_1"/>
    <child link="hexapod/leg_0/link_2"/>
    <origin rpy="0 0 0" xyz="0.132 0 0.0165"/>
    <axis xyz="0 0 1"/>
    <limit effort="100" lower="-2.356194490192345" upper="2.356194490192345" velocity="1.7453292519943295"/>
  </joint>
  <link name="hexapod/leg_0/link_2">
    <visual>
      <origin rpy="0 0 0" xyz="0 0 0"/>
      <geometry>
        <mesh filename="meshes/visual/leg_2_left.stl"/>
      </geometry>
    </visual>
    <collision>
      <origin rpy="0 0 0" xyz="0 0 0"/>
      <geometry>
        <mesh filename="meshes/collision/leg_2_left.stl"/>
      </geometry>
    </collision>
    <inertial>
      <mass value="0.0467"/>
      <origin rpy="0 0 0" xyz="0.08534 -0.00854 0.00075"/>
      <!-- <inertia ixx="0.0002" ixy="-2.666e-05" ixz="0." iyy="9.028e-06" 
					iyz="0." izz="0.0002" /> </inertial> -->
      <inertia ixx="1e-2" ixy="0.0" ixz="0.0" iyy="1e-2" iyz="0.0" izz="1e-2"/>
    </inertial>
  </link>
  <joint name="hexapod/leg_1/joint_0" type="revolute">
    <parent link="hexapod/body"/>
    <child link="hexapod/leg_1/link_0"/>
    <origin rpy="0 0 -1.5707963267948966" xyz="0.080 -0.058 -0.014"/>
    <axis xyz="0 0 1"/>
    <limit effort="100" lower="-2.356194490192345" upper="2.356194490192345" velocity="1.7453292519943295"/>
  </joint>
  <link name="hexapod/leg_1/link_0">
    <visual>
      <origin rpy="0 0 0" xyz="0 0 0"/>
      <geometry>
        <mesh filename="meshes/visual/leg_0_right.stl"/>
      </geometry>
    </visual>
    <collision>
      <origin rpy="0 0 0" xyz="0 0 0"/>
      <geometry>
        <mesh filename="meshes/collision/leg_0_right.stl"/>
      </geometry>
    </collision>
    <inertial>
      <mass value="0.042061"/>
      <origin rpy="0 0 0" xyz="0.037232 -0.010178 -0.005231"/>
      <!--<inertia ixx="6.67e-06" ixy="-1.158e-06" ixz="1.13e-06" iyy="2.753e-05" 
					iyz="1.78e-06" izz="2.86e-05" /> </inertial> -->
      <inertia ixx="1e-2" ixy="0.0" ixz="0.0" iyy="1e-2" iyz="0.0" izz="1e-2"/>
    </inertial>
  </link>
  <link name="hexapod/leg_1/motor_1">
    <visual>
      <origin rpy="0 0 0" xyz="0 0 0"/>
      <geometry>
        <mesh filename="meshes/visual/motor.stl"/>
      </geometry>
    </visual>
    <collision>
      <origin rpy="0 0 0" xyz="0 0 0"/>
      <geometry>
        <mesh filename="meshes/collision/motor.stl"/>
      </geometry>
    </collision>
    <inertial>
      <mass value="0.056"/>
      <origin rpy="0 0 0" xyz="8.6786e-5 0 -0.007678"/>
      <inertia ixx="1e-3" ixy="0" ixz="0" iyy="1e-3" iyz="0" izz="1e-3"/>
    </inertial>
  </link>
  <joint name="hexapod/leg_1_motor_1_joint" type="fixed">
    <parent link="hexapod/leg_1/link_0"/>
    <child link="hexapod/leg_1/motor_1"/>
    <origin rpy="-1.5707963267948966 0 0" xyz="0.0465 0.01225 -0.0145"/>
  </joint>
  <joint name="hexapod/leg_1/joint_1" type="revolute">
    <parent link="hexapod/leg_1/link_0"/>
    <child link="hexapod/leg_1/link_1"/>
    <origin rpy="-1.5707963267948966 0 0" xyz="0.062 0.032 -0.01375"/>
    <axis xyz="0 0 1"/>
    <limit effort="100" lower="-2.356194490192345" upper="2.356194490192345" velocity="1.7453292519943295"/>
  </joint>
  <link name="hexapod/leg_1/link_1">
    <visual>
      <origin rpy="0 0 0" xyz="0 0 0"/>
      <geometry>
        <mesh filename="meshes/visual/leg_1.stl"/>
      </geometry>
    </visual>
    <collision>
      <origin rpy="0 0 0" xyz="0 0 0"/>
      <geometry>
        <mesh filename="meshes/collision/leg_1.stl"/>
      </geometry>
    </collision>
    <inertial>
      <mass value="0.03207"/>
      <origin rpy="0 0 0" xyz="0.06009 0 0.00075"/>
      <!-- <inertia ixx="3.44e-06" ixy="0." ixz="0." iyy="6.75e-05" iyz="0." 
					izz="7.091e-05" /> </inertial> -->
      <inertia ixx="1e-2" ixy="0.0" ixz="0.0" iyy="1e-2" iyz="0.0" izz="1e-2"/>
    </inertial>
  </link>
  <link name="hexapod/leg_1/motor_2">
    <visual>
      <origin rpy="0 0 0" xyz="0 0 0"/>
      <geometry>
        <mesh filename="meshes/visual/motor.stl"/>
      </geometry>
    </visual>
    <collision>
      <origin rpy="0 0 0" xyz="0 0 0"/>
      <geometry>
        <mesh filename="meshes/collision/motor.stl"/>
      </geometry>
    </collision>
    <inertial>
      <mass value="0.056"/>
      <origin rpy="0 0 0" xyz="8.6786e-5 0 -0.007678"/>
      <inertia ixx="1e-3" ixy="0" ixz="0" iyy="1e-3" iyz="0" izz="1e-3"/>
    </inertial>
  </link>
  <joint name="hexapod/leg_1_motor_2_joint" type="fixed">
    <parent link="hexapod/leg_1/link_1"/>
    <child link="hexapod/leg_1/motor_2"/>
    <origin rpy="0 0 0" xyz="0.1165 0 -0.0032"/>
  </joint>
  <joint name="hexapod/leg_1/joint_2" type="revolute">
    <parent link="hexapod/leg_1/link_1"/>
    <child link="hexapod/leg_1/link_2"/>
    <origin rpy="0 0 0" xyz="0.132 0 0.0165"/>
    <axis xyz="0 0 1"/>
    <limit effort="100" lower="-2.356194490192345" upper="2.356194490192345" velocity="1.7453292519943295"/>
  </joint>
  <link name="hexapod/leg_1/link_2">
    <visual>
      <origin rpy="0 0 0" xyz="0 0 0"/>
      <geometry>
        <mesh filename="meshes/visual/leg_2_right.stl"/>
      </geometry>
    </visual>
    <collision>
      <origin rpy="0 0 0" xyz="0 0 0"/>
      <geometry>
        <mesh filename="meshes/collision/leg_2_right.stl"/>
      </geometry>
    </collision>
    <inertial>
      <mass value="0.0467"/>
      <origin rpy="0 0 0" xyz="0.08534 0.00854 0.00075"/>
      <!-- <inertia ixx="0.0002" ixy="-2.666e-05" ixz="0." iyy="9.028e-06" 
					iyz="0." izz="0.0002" /> </inertial> -->
      <inertia ixx="1e-2" ixy="0.0" ixz="0.0" iyy="1e-2" iyz="0.0" izz="1e-2"/>
    </inertial>
  </link>
  <joint name="hexapod/leg_2/joint_0" type="revolute">
    <parent link="hexapod/body"/>
    <child link="hexapod/leg_2/link_0"/>
    <origin rpy="0 0 1.5707963267948966" xyz="0.0 0.075 -0.014"/>
    <axis xyz="0 0 1"/>
    <limit effort="100" lower="-2.356194490192345" upper="2.356194490192345" velocity="1.7453292519943295"/>
  </joint>
  <link name="hexapod/leg_2/link_0">
    <visual>
      <origin rpy="0 0 0" xyz="0 0 0"/>
      <geometry>
        <mesh filename="meshes/visual/leg_0_left.stl"/>
      </geometry>
    </visual>
    <collision>
      <origin rpy="0 0 0" xyz="0 0 0"/>
      <geometry>
        <mesh filename="meshes/collision/leg_0_left.stl"/>
      </geometry>
    </collision>
    <inertial>
      <mass value="0.042061"/>
      <origin rpy="0 0 0" xyz="0.037232 0.010178 -0.005231"/>
      <!--<inertia ixx="6.67e-06" ixy="-1.158e-06" ixz="1.13e-06" iyy="2.753e-05" 
					iyz="1.78e-06" izz="2.86e-05" /> </inertial> -->
      <inertia ixx="1e-2" ixy="0.0" ixz="0.0" iyy="1e-2" iyz="0.0" izz="1e-2"/>
    </inertial>
  </link>
  <link name="hexapod/leg_2/motor_1">
    <visual>
      <origin rpy="0 0 0" xyz="0 0 0"/>
      <geometry>
        <mesh filename="meshes/visual/motor.stl"/>
      </geometry>
    </visual>
    <collision>
      <origin rpy="0 0 0" xyz="0 0 0"/>
      <geometry>
        <mesh filename="meshes/collision/motor.stl"/>
      </geometry>
    </collision>
    <inertial>
      <mass value="0.056"/>
      <origin rpy="0 0 0" xyz="8.6786e-5 0 -0.007678"/>
      <inertia ixx="1e-3" ixy="0" ixz="0" iyy="1e-3" iyz="0" izz="1e-3"/>
    </inertial>
  </link>
  <joint name="hexapod/leg_2_motor_1_joint" type="fixed">
    <parent link="hexapod/leg_2/link_0"/>
    <child link="hexapod/leg_2/motor_1"/>
    <origin rpy="1.5707963267948966 0 0" xyz="0.0465 -0.01225 -0.0145"/>
  </joint>
  <joint name="hexapod/leg_2/joint_1" type="revolute">
    <parent link="hexapod/leg_2/link_0"/>
    <child link="hexapod/leg_2/link_1"/>
    <origin rpy="1.5707963267948966 0 0" xyz="0.062 -0.032 -0.01375"/>
    <axis xyz="0 0 1"/>
    <limit effort="100" lower="-2.356194490192345" upper="2.356194490192345" velocity="1.7453292519943295"/>
  </joint>
  <link name="hexapod/leg_2/link_1">
    <visual>
      <origin rpy="0 0 0" xyz="0 0 0"/>
      <geometry>
        <mesh filename="meshes/visual/leg_1.stl"/>
      </geometry>
    </visual>
    <collision>
      <origin rpy="0 0 0" xyz="0 0 0"/>
      <geometry>
        <mesh filename="meshes/collision/leg_1.stl"/>
      </geometry>
    </collision>
    <inertial>
      <mass value="0.03207"/>
      <origin rpy="0 0 0" xyz="0.06009 0 0.00075"/>
      <!-- <inertia ixx="3.44e-06" ixy="0." ixz="0." iyy="6.75e-05" iyz="0." 
					izz="7.091e-05" /> </inertial> -->
      <inertia ixx="1e-2" ixy="0.0" ixz="0.0" iyy="1e-2" iyz="0.0" izz="1e-2"/>
    </inertial>
  </link>
  <link name="hexapod/leg_2/motor_2">
    <visual>
      <origin rpy="0 0 0" xyz="0 0 0"/>
      <geometry>
        <mesh filename="meshes/visual/motor.stl"/>
      </geometry>
    </visual>
    <collision>
      <origin rpy="0 0 0" xyz="0 0 0"/>
      <geometry>
        <mesh filename="meshes/collision/motor.stl"/>
      </geometry>
    </collision>
    <inertial>
      <mass value="0.056"/>
      <origin rpy="0 0 0" xyz="8.6786e-5 0 -0.007678"/>
      <inertia ixx="1e-3" ixy="0" ixz="0" iyy="1e-3" iyz="0" izz="1e-3"/>
    </inertial>
  </link>
  <joint name="hexapod/leg_2_motor_2_joint" type="fixed">
    <parent link="hexapod/leg_2/link_1"/>
    <child link="hexapod/leg_2/motor_2"/>
    <origin rpy="0 0 0" xyz="0.1165 0 -0.0032"/>
  </joint>
  <joint name="hexapod/leg_2/joint_2" type="revolute">
    <parent link="hexapod/leg_2/link_1"/>
    <child link="hexapod/leg_2/link_2"/>
    <origin rpy="0 0 0" xyz="0.132 0 0.0165"/>
    <axis xyz="0 0 1"/>
    <limit effort="100" lower="-2.356194490192345" upper="2.356194490192345" velocity="1.7453292519943295"/>
  </joint>
  <link name="hexapod/leg_2/link_2">
    <visual>
      <origin rpy="0 0 0" xyz="0 0 0"/>
      <geometry>
        <mesh filename="meshes/visual/leg_2_left.stl"/>
      </geometry>
    </visual>
    <collision>
      <origin rpy="0 0 0" xyz="0 0 0"/>
      <geometry>
        <mesh filename="meshes/collision/leg_2_left.stl"/>
      </geometry>
    </collision>
    <inertial>
      <mass value="0.0467"/>
      <origin rpy="0 0 0" xyz="0.08534 -0.00854 0.00075"/>
      <!-- <inertia ixx="0.0002" ixy="-2.666e-05" ixz="0." iyy="9.028e-06" 
					iyz="0." izz="0.0002" /> </inertial> -->
      <inertia ixx="1e-2" ixy="0.0" ixz="0.0" iyy="1e-2" iyz="0.0" izz="1e-2"/>
    </inertial>
  </link>
  <joint name="hexapod/leg_3/joint_0" type="revolute">
    <parent link="hexapod/body"/>
    <child link="hexapod/leg_3/link_0"/>
    <origin rpy="0 0 -1.5707963267948966" xyz="0.0 -0.075 -0.014"/>
    <axis xyz="0 0 1"/>
    <limit effort="100" lower="-2.356194490192345" upper="2.356194490192345" velocity="1.7453292519943295"/>
  </joint>
  <link name="hexapod/leg_3/link_0">
    <visual>
      <origin rpy="0 0 0" xyz="0 0 0"/>
      <geometry>
        <mesh filename="meshes/visual/leg_0_right.stl"/>
      </geometry>
    </visual>
    <collision>
      <origin rpy="0 0 0" xyz="0 0 0"/>
      <geometry>
        <mesh filename="meshes/collision/leg_0_right.stl"/>
      </geometry>
    </collision>
    <inertial>
      <mass value="0.042061"/>
      <origin rpy="0 0 0" xyz="0.037232 -0.010178 -0.005231"/>
      <!--<inertia ixx="6.67e-06" ixy="-1.158e-06" ixz="1.13e-06" iyy="2.753e-05" 
					iyz="1.78e-06" izz="2.86e-05" /> </inertial> -->
      <inertia ixx="1e-2" ixy="0.0" ixz="0.0" iyy="1e-2" iyz="0.0" izz="1e-2"/>
    </inertial>
  </link>
  <link name="hexapod/leg_3/motor_1">
    <visual>
      <origin rpy="0 0 0" xyz="0 0 0"/>
      <geometry>
        <mesh filename="meshes/visual/motor.stl"/>
      </geometry>
    </visual>
    <collision>
      <origin rpy="0 0 0" xyz="0 0 0"/>
      <geometry>
        <mesh filename="meshes/collision/motor.stl"/>
      </geometry>
    </collision>
    <inertial>
      <mass value="0.056"/>
      <origin rpy="0 0 0" xyz="8.6786e-5 0 -0.007678"/>
      <inertia ixx="1e-3" ixy="0" ixz="0" iyy="1e-3" iyz="0" izz="1e-3"/>
    </inertial>
  </link>
  <joint name="hexapod/leg_3_motor_1_joint" type="fixed">
    <parent link="hexapod/leg_3/link_0"/>
    <child link="hexapod/leg_3/motor_1"/>
    <origin rpy="-1.5707963267948966 0 0" xyz="0.0465 0.01225 -0.0145"/>
  </joint>
  <joint name="hexapod/leg_3/joint_1" type="revolute">
    <parent link="hexapod/leg_3/link_0"/>
    <child link="hexapod/leg_3/link_1"/>
    <origin rpy="-1.5707963267948966 0 0" xyz="0.062 0.032 -0.01375"/>
    <axis xyz="0 0 1"/>
    <limit effort="100" lower="-2.356194490192345" upper="2.356194490192345" velocity="1.7453292519943295"/>
  </joint>
  <link name="hexapod/leg_3/link_1">
    <visual>
      <origin rpy="0 0 0" xyz="0 0 0"/>
      <geometry>
        <mesh filename="meshes/visual/leg_1.stl"/>
      </geometry>
    </visual>
    <collision>
      <origin rpy="0 0 0" xyz="0 0 0"/>
      <geometry>
        <mesh filename="meshes/collision/leg_1.stl"/>
      </geometry>
    </collision>
    <inertial>
      <mass value="0.03207"/>
      <origin rpy="0 0 0" xyz="0.06009 0 0.00075"/>
      <!-- <inertia ixx="3.44e-06" ixy="0." ixz="0." iyy="6.75e-05" iyz="0." 
					izz="7.091e-05" /> </inertial> -->
      <inertia ixx="1e-2" ixy="0.0" ixz="0.0" iyy="1e-2" iyz="0.0" izz="1e-2"/>
    </inertial>
  </link>
  <link name="hexapod/leg_3/motor_2">
    <visual>
      <origin rpy="0 0 0" xyz="0 0 0"/>
      <geometry>
        <mesh filename="meshes/visual/motor.stl"/>
      </geometry>
    </visual>
    <collision>
      <origin rpy="0 0 0" xyz="0 0 0"/>
      <geometry>
        <mesh filename="meshes/collision/motor.stl"/>
      </geometry>
    </collision>
    <inertial>
      <mass value="0.056"/>
      <origin rpy="0 0 0" xyz="8.6786e-5 0 -0.007678"/>
      <inertia ixx="1e-3" ixy="0" ixz="0" iyy="1e-3" iyz="0" izz="1e-3"/>
    </inertial>
  </link>
  <joint name="hexapod/leg_3_motor_2_joint" type="fixed">
    <parent link="hexapod/leg_3/link_1"/>
    <child link="hexapod/leg_3/motor_2"/>
    <origin rpy="0 0 0" xyz="0.1165 0 -0.0032"/>
  </joint>
  <joint name="hexapod/leg_3/joint_2" type="revolute">
    <parent link="hexapod/leg_3/link_1"/>
    <child link="hexapod/leg_3/link_2"/>
    <origin rpy="0 0 0" xyz="0.132 0 0.0165"/>
    <axis xyz="0 0 1"/>
    <limit effort="100" lower="-2.356194490192345" upper="2.356194490192345" velocity="1.7453292519943295"/>
  </joint>
  <link name="hexapod/leg_3/link_2">
    <visual>
      <origin rpy="0 0 0" xyz="0 0 0"/>
      <geometry>
        <mesh filename="meshes/visual/leg_2_right.stl"/>
      </geometry>
    </visual>
    <collision>
      <origin rpy="0 0 0" xyz="0 0 0"/>
      <geometry>
        <mesh filename="meshes/collision/leg_2_right.stl"/>
      </geometry>
    </collision>
    <inertial>
      <mass value="0.0467"/>
      <origin rpy="0 0 0" xyz="0.08534 0.00854 0.00075"/>
      <!-- <inertia ixx="0.0002" ixy="-2.666e-05" ixz="0." iyy="9.028e-06" 
					iyz="0." izz="0.0002" /> </inertial> -->
      <inertia ixx="1e-2" ixy="0.0" ixz="0.0" iyy="1e-2" iyz="0.0" izz="1e-2"/>
    </inertial>
  </link>
  <joint name="hexapod/leg_4/joint_0" type="revolute">
    <parent link="hexapod/body"/>
    <child link="hexapod/leg_4/link_0"/>
    <origin rpy="0 0 1.5707963267948966" xyz="-0.080 0.058 -0.014"/>
    <axis xyz="0 0 1"/>
    <limit effort="100" lower="-2.356194490192345" upper="2.356194490192345" velocity="1.7453292519943295"/>
  </joint>
  <link name="hexapod/leg_4/link_0">
    <visual>
      <origin rpy="0 0 0" xyz="0 0 0"/>
      <geometry>
        <mesh filename="meshes/visual/leg_0_left.stl"/>
      </geometry>
    </visual>
    <collision>
      <origin rpy="0 0 0" xyz="0 0 0"/>
      <geometry>
        <mesh filename="meshes/collision/leg_0_left.stl"/>
      </geometry>
    </collision>
    <inertial>
      <mass value="0.042061"/>
      <origin rpy="0 0 0" xyz="0.037232 0.010178 -0.005231"/>
      <!--<inertia ixx="6.67e-06" ixy="-1.158e-06" ixz="1.13e-06" iyy="2.753e-05" 
					iyz="1.78e-06" izz="2.86e-05" /> </inertial> -->
      <inertia ixx="1e-2" ixy="0.0" ixz="0.0" iyy="1e-2" iyz="0.0" izz="1e-2"/>
    </inertial>
  </link>
  <link name="hexapod/leg_4/motor_1">
    <visual>
      <origin rpy="0 0 0" xyz="0 0 0"/>
      <geometry>
        <mesh filename="meshes/visual/motor.stl"/>
      </geometry>
    </visual>
    <collision>
      <origin rpy="0 0 0" xyz="0 0 0"/>
      <geometry>
        <mesh filename="meshes/collision/motor.stl"/>
      </geometry>
    </collision>
    <inertial>
      <mass value="0.056"/>
      <origin rpy="0 0 0" xyz="8.6786e-5 0 -0.007678"/>
      <inertia ixx="1e-3" ixy="0" ixz="0" iyy="1e-3" iyz="0" izz="1e-3"/>
    </inertial>
  </link>
  <joint name="hexapod/leg_4_motor_1_joint" type="fixed">
    <parent link="hexapod/leg_4/link_0"/>
    <child link="hexapod/leg_4/motor_1"/>
    <origin rpy="1.5707963267948966 0 0" xyz="0.0465 -0.01225 -0.0145"/>
  </joint>
  <joint name="hexapod/leg_4/joint_1" type="revolute">
    <parent link="hexapod/leg_4/link_0"/>
    <child link="hexapod/leg_4/link_1"/>
    <origin rpy="1.5707963267948966 0 0" xyz="0.062 -0.032 -0.01375"/>
    <axis xyz="0 0 1"/>
    <limit effort="100" lower="-2.356194490192345" upper="2.356194490192345" velocity="1.7453292519943295"/>
  </joint>
  <link name="hexapod/leg_4/link_1">
    <visual>
      <origin rpy="0 0 0" xyz="0 0 0"/>
      <geometry>
        <mesh filename="meshes/visual/leg_1.stl"/>
      </geometry>
    </visual>
    <collision>
      <origin rpy="0 0 0" xyz="0 0 0"/>
      <geometry>
        <mesh filename="meshes/collision/leg_1.stl"/>
      </geometry>
    </collision>
    <inertial>
      <mass value="0.03207"/>
      <origin rpy="0 0 0" xyz="0.06009 0 0.00075"/>
      <!-- <inertia ixx="3.44e-06" ixy="0." ixz="0." iyy="6.75e-05" iyz="0." 
					izz="7.091e-05" /> </inertial> -->
      <inertia ixx="1e-2" ixy="0.0" ixz="0.0" iyy="1e-2" iyz="0.0" izz="1e-2"/>
    </inertial>
  </link>
  <link name="hexapod/leg_4/motor_2">
    <visual>
      <origin rpy="0 0 0" xyz="0 0 0"/>
      <geometry>
        <mesh filename="meshes/visual/motor.stl"/>
      </geometry>
    </visual>
    <collision>
      <origin rpy="0 0 0" xyz="0 0 0"/>
      <geometry>
        <mesh filename="meshes/collision/motor.stl"/>
      </geometry>
    </collision>
    <inertial>
      <mass value="0.056"/>
      <origin rpy="0 0 0" xyz="8.6786e-5 0 -0.007678"/>
      <inertia ixx="1e-3" ixy="0" ixz="0" iyy="1e-3" iyz="0" izz="1e-3"/>
    </inertial>
  </link>
  <joint name="hexapod/leg_4_motor_2_joint" type="fixed">
    <parent link="hexapod/leg_4/link_1"/>
    <child link="hexapod/leg_4/motor_2"/>
    <origin rpy="0 0 0" xyz="0.1165 0 -0.0032"/>
  </joint>
  <joint name="hexapod/leg_4/joint_2" type="revolute">
    <parent link="hexapod/leg_4/link_1"/>
    <child link="hexapod/leg_4/link_2"/>
    <origin rpy="0 0 0" xyz="0.132 0 0.0165"/>
    <axis xyz="0 0 1"/>
    <limit effort="100" lower="-2.356194490192345" upper="2.356194490192345" velocity="1.7453292519943295"/>
  </joint>
  <link name="hexapod/leg_4/link_2">
    <visual>
      <origin rpy="0 0 0" xyz="0 0 0"/>
      <geometry>
        <mesh filename="meshes/visual/leg_2_left.stl"/>
      </geometry>
    </visual>
    <collision>
      <origin rpy="0 0 0" xyz="0 0 0"/>
      <geometry>
        <mesh filename="meshes/collision/leg_2_left.stl"/>
      </geometry>
    </collision>
    <inertial>
      <mass value="0.0467"/>
      <origin rpy="0 0 0" xyz="0.08534 -0.00854 0.00075"/>
      <!-- <inertia ixx="0.0002" ixy="-2.666e-05" ixz="0." iyy="9.028e-06" 
					iyz="0." izz="0.0002" /> </inertial> -->
      <inertia ixx="1e-2" ixy="0.0" ixz="0.0" iyy="1e-2" iyz="0.0" izz="1e-2"/>
    </inertial>
  </link>
  <joint name="hexapod/leg_5/joint_0" type="revolute">
    <parent link="hexapod/body"/>
    <child link="hexapod/leg_5/link_0"/>
    <origin rpy="0 0 -1.5707963267948966" xyz="-0.080 -0.058 -0.014"/>
    <axis xyz="0 0 1"/>
    <limit effort="100" lower="-2.356194490192345" upper="2.356194490192345" velocity="1.7453292519943295"/>
  </joint>
  <link name="hexapod/leg_5/link_0">
    <visual>
      <origin rpy="0 0 0" xyz="0 0 0"/>
      <geometry>
        <mesh filename="meshes/visual/leg_0_right.stl"/>
      </geometry>
    </visual>
    <collision>
      <origin rpy="0 0 0" xyz="0 0 0"/>
      <geometry>
        <mesh filename="meshes/collision/leg_0_right.stl"/>
      </geometry>
    </collision>
    <inertial>
      <mass value="0.042061"/>
      <origin rpy="0 0 0" xyz="0.037232 -0.010178 -0.005231"/>
      <!--<inertia ixx="6.67e-06" ixy="-1.158e-06" ixz="1.13e-06" iyy="2.753e-05" 
					iyz="1.78e-06" izz="2.86e-05" /> </inertial> -->
      <inertia ixx="1e-2" ixy="0.0" ixz="0.0" iyy="1e-2" iyz="0.0" izz="1e-2"/>
    </inertial>
  </link>
  <link name="hexapod/leg_5/motor_1">
    <visual>
      <origin rpy="0 0 0" xyz="0 0 0"/>
      <geometry>
        <mesh filename="meshes/visual/motor.stl"/>
      </geometry>
    </visual>
    <collision>
      <origin rpy="0 0 0" xyz="0 0 0"/>
      <geometry>
        <mesh filename="meshes/collision/motor.stl"/>
      </geometry>
    </collision>
    <inertial>
      <mass value="0.056"/>
      <origin rpy="0 0 0" xyz="8.6786e-5 0 -0.007678"/>
      <inertia ixx="1e-3" ixy="0" ixz="0" iyy="1e-3" iyz="0" izz="1e-3"/>
    </inertial>
  </link>
  <joint name="hexapod/leg_5_motor_1_joint" type="fixed">
    <parent link="hexapod/leg_5/link_0"/>
    <child link="hexapod/leg_5/motor_1"/>
    <origin rpy="-1.5707963267948966 0 0" xyz="0.0465 0.01225 -0.0145"/>
  </joint>
  <joint name="hexapod/leg_5/joint_1" type="revolute">
    <parent link="hexapod/leg_5/link_0"/>
    <child link="hexapod/leg_5/link_1"/>
    <origin rpy="-1.5707963267948966 0 0" xyz="0.062 0.032 -0.01375"/>
    <axis xyz="0 0 1"/>
    <limit effort="100" lower="-2.356194490192345" upper="2.356194490192345" velocity="1.7453292519943295"/>
  </joint>
  <link name="hexapod/leg_5/link_1">
    <visual>
      <origin rpy="0 0 0" xyz="0 0 0"/>
      <geometry>
        <mesh filename="meshes/visual/leg_1.stl"/>
      </geometry>
    </visual>
    <collision>
      <origin rpy="0 0 0" xyz="0 0 0"/>
      <geometry>
        <mesh filename="meshes/collision/leg_1.stl"/>
      </geometry>
    </collision>
    <inertial>
      <mass value="0.03207"/>
      <origin rpy="0 0 0" xyz="0.06009 0 0.00075"/>
      <!-- <inertia ixx="3.44e-06" ixy="0." ixz="0." iyy="6.75e-05" iyz="0." 
					izz="7.091e-05" /> </inertial> -->
      <inertia ixx="1e-2" ixy="0.0" ixz="0.0" iyy="1e-2" iyz="0.0" izz="1e-2"/>
    </inertial>
  </link>
  <link name="hexapod/leg_5/motor_2">
    <visual>
      <origin rpy="0 0 0" xyz="0 0 0"/>
      <geometry>
        <mesh filename="meshes/visual/motor.stl"/>
      </geometry>
    </visual>
    <collision>
      <origin rpy="0 0 0" xyz="0 0 0"/>
      <geometry>
        <mesh filename="meshes/collision/motor.stl"/>
      </geometry>
    </collision>
    <inertial>
      <mass value="0.056"/>
      <origin rpy="0 0 0" xyz="8.6786e-5 0 -0.007678"/>
      <inertia ixx="1e-3" ixy="0" ixz="0" iyy="1e-3" iyz="0" izz="1e-3"/>
    </inertial>
  </link>
  <joint name="hexapod/leg_5_motor_2_joint" type="fixed">
    <parent link="hexapod/leg_5/link_1"/>
    <child link="hexapod/leg_5/motor_2"/>
    <origin rpy="0 0 0" xyz="0.1165 0 -0.0032"/>
  </joint>
  <joint name="hexapod/leg_5/joint_2" type="revolute">
    <parent link="hexapod/leg_5/link_1"/>
    <child link="hexapod/leg_5/link_2"/>
    <origin rpy="0 0 0" xyz="0.132 0 0.0165"/>
    <axis xyz="0 0 1"/>
    <limit effort="100" lower="-2.356194490192345" upper="2.356194490192345" velocity="1.7453292519943295"/>
  </joint>
  <link name="hexapod/leg_5/link_2">
    <visual>
      <origin rpy="0 0 0" xyz="0 0 0"/>
      <geometry>
        <mesh filename="meshes/visual/leg_2_right.stl"/>
      </geometry>
    </visual>
    <collision>
      <origin rpy="0 0 0" xyz="0 0 0"/>
      <geometry>
        <mesh filename="meshes/collision/leg_2_right.stl"/>
      </geometry>
    </collision>
    <inertial>
      <mass value="0.0467"/>
      <origin rpy="0 0 0" xyz="0.08534 0.00854 0.00075"/>
      <!-- <inertia ixx="0.0002" ixy="-2.666e-05" ixz="0." iyy="9.028e-06" 
					iyz="0." izz="0.0002" /> </inertial> -->
      <inertia ixx="1e-2" ixy="0.0" ixz="0.0" iyy="1e-2" iyz="0.0" izz="1e-2"/>
    </inertial>
  </link>
  <gazebo reference="hexapod/body">
    <material>Gazebo/Grey</material>
    <mu1>0.2</mu1>
    <mu2>0.2</mu2>
    <selfCollide>1</selfCollide>
  </gazebo>
  <gazebo reference="hexapod/leg_0/link_0">
    <material>Gazebo/Grey</material>
    <mu1>0.2</mu1>
    <mu2>0.2</mu2>
    <selfCollide>1</selfCollide>
  </gazebo>
  <gazebo reference="hexapod/leg_0/link_1">
    <material>Gazebo/Grey</material>
    <mu1>0.2</mu1>
    <mu2>0.2</mu2>
    <selfCollide>1</selfCollide>
  </gazebo>
  <gazebo reference="hexapod/leg_0/link_2">
    <material>Gazebo/Grey</material>
    <mu1>0.2</mu1>
    <mu2>0.2</mu2>
    <selfCollide>1</selfCollide>
  </gazebo>
  <gazebo reference="hexapod/leg_1/link_0">
    <material>Gazebo/Grey</material>
    <mu1>0.2</mu1>
    <mu2>0.2</mu2>
    <selfCollide>1</selfCollide>
  </gazebo>
  <gazebo reference="hexapod/leg_1/link_1">
    <material>Gazebo/Grey</material>
    <mu1>0.2</mu1>
    <mu2>0.2</mu2>
    <selfCollide>1</selfCollide>
  </gazebo>
  <gazebo reference="hexapod/leg_1/link_2">
    <material>Gazebo/Grey</material>
    <mu1>0.2</mu1>
    <mu2>0.2</mu2>
    <selfCollide>1</selfCollide>
  </gazebo>
  <gazebo reference="hexapod/leg_2/link_0">
    <material>Gazebo/Grey</material>
    <mu1>0.2</mu1>
    <mu2>0.2</mu2>
    <selfCollide>1</selfCollide>
  </gazebo>
  <gazebo reference="hexapod/leg_2/link_1">
    <material>Gazebo/Grey</material>
    <mu1>0.2</mu1>
    <mu2>0.2</mu2>
    <selfCollide>1</selfCollide>
  </gazebo>
  <gazebo reference="hexapod/leg_2/link_2">
    <material>Gazebo/Grey</material>
    <mu1>0.2</mu1>
    <mu2>0.2</mu2>
    <selfCollide>1</selfCollide>
  </gazebo>
  <gazebo reference="hexapod/leg_3/link_0">
    <material>Gazebo/Grey</material>
    <mu1>0.2</mu1>
    <mu2>0.2</mu2>
    <selfCollide>1</selfCollide>
  </gazebo>
  <gazebo reference="hexapod/leg_3/link_1">
    <material>Gazebo/Grey</material>
    <mu1>0.2</mu1>
    <mu2>0.2</mu2>
    <selfCollide>1</selfCollide>
  </gazebo>
  <gazebo reference="hexapod/leg_3/link_2">
    <material>Gazebo/Grey</material>
    <mu1>0.2</mu1>
    <mu2>0.2</mu2>
    <selfCollide>1</selfCollide>
  </gazebo>
  <gazebo reference="hexapod/leg_4/link_0">
    <material>Gazebo/Grey</material>
    <mu1>0.2</mu1>
    <mu2>0.2</mu2>
    <selfCollide>1</selfCollide>
  </gazebo>
  <gazebo reference="hexapod/leg_4/link_1">
    <material>Gazebo/Grey</material>
    <mu1>0.2</mu1>
    <mu2>0.2</mu2>
    <selfCollide>1</selfCollide>
  </gazebo>
  <gazebo reference="hexapod/leg_4/link_2">
    <material>Gazebo/Grey</material>
    <mu1>0.2</mu1>
    <mu2>0.2</mu2>
    <selfCollide>1</selfCollide>
  </gazebo>
  <gazebo reference="hexapod/leg_5/link_0">
    <material>Gazebo/Grey</material>
    <mu1>0.2</mu1>
    <mu2>0.2</mu2>
    <selfCollide>1</selfCollide>
  </gazebo>
  <gazebo reference="hexapod/leg_5/link_1">
    <material>Gazebo/Grey</material>
    <mu1>0.2</mu1>
    <mu2>0.2</mu2>
    <selfCollide>1</selfCollide>
  </gazebo>
  <gazebo reference="hexapod/leg_5/link_2">
    <material>Gazebo/Grey</material>
    <mu1>0.2</mu1>
    <mu2>0.2</mu2>
    <selfCollide>1</selfCollide>
  </gazebo>
  <gazebo reference="hexapod/leg_0/motor_0">
    <material>Gazebo/White</material>
    <mu1>0.2</mu1>
    <mu2>0.2</mu2>
    <selfCollide>1</selfCollide>
  </gazebo>
  <gazebo reference="hexapod/leg_0/motor_1">
    <material>Gazebo/White</material>
    <mu1>0.2</mu1>
    <mu2>0.2</mu2>
    <selfCollide>1</selfCollide>
  </gazebo>
  <gazebo reference="hexapod/leg_0/motor_2">
    <material>Gazebo/White</material>
    <mu1>0.2</mu1>
    <mu2>0.2</mu2>
    <selfCollide>1</selfCollide>
  </gazebo>
  <gazebo reference="hexapod/leg_1/motor_0">
    <material>Gazebo/White</material>
    <mu1>0.2</mu1>
    <mu2>0.2</mu2>
    <selfCollide>1</selfCollide>
  </gazebo>
  <gazebo reference="hexapod/leg_1/motor_1">
    <material>Gazebo/White</material>
    <mu1>0.2</mu1>
    <mu2>0.2</mu2>
    <selfCollide>1</selfCollide>
  </gazebo>
  <gazebo reference="hexapod/leg_1/motor_2">
    <material>Gazebo/White</material>
    <mu1>0.2</mu1>
    <mu2>0.2</mu2>
    <selfCollide>1</selfCollide>
  </gazebo>
  <gazebo reference="hexapod/leg_2/motor_0">
    <material>Gazebo/White</material>
    <mu1>0.2</mu1>
    <mu2>0.2</mu2>
    <selfCollide>1</selfCollide>
  </gazebo>
  <gazebo reference="hexapod/leg_2/motor_1">
    <material>Gazebo/White</material>
    <mu1>0.2</mu1>
    <mu2>0.2</mu2>
    <selfCollide>1</selfCollide>
  </gazebo>
  <gazebo reference="hexapod/leg_2/motor_2">
    <material>Gazebo/White</material>
    <mu1>0.2</mu1>
    <mu2>0.2</mu2>
    <selfCollide>1</selfCollide>
  </gazebo>
  <gazebo reference="hexapod/leg_3/motor_0">
    <material>Gazebo/White</material>
    <mu1>0.2</mu1>
    <mu2>0.2</mu2>
    <selfCollide>1</selfCollide>
  </gazebo>
  <gazebo reference="hexapod/leg_3/motor_1">
    <material>Gazebo/White</material>
    <mu1>0.2</mu1>
    <mu2>0.2</mu2>
    <selfCollide>1</selfCollide>
  </gazebo>
  <gazebo reference="hexapod/leg_3/motor_2">
    <material>Gazebo/White</material>
    <mu1>0.2</mu1>
    <mu2>0.2</mu2>
    <selfCollide>1</selfCollide>
  </gazebo>
  <gazebo reference="hexapod/leg_4/motor_0">
    <material>Gazebo/White</material>
    <mu1>0.2</mu1>
    <mu2>0.2</mu2>
    <selfCollide>1</selfCollide>
  </gazebo>
  <gazebo reference="hexapod/leg_4/motor_1">
    <material>Gazebo/White</material>
    <mu1>0.2</mu1>
    <mu2>0.2</mu2>
    <selfCollide>1</selfCollide>
  </gazebo>
  <gazebo reference="hexapod/leg_4/motor_2">
    <material>Gazebo/White</material>
    <mu1>0.2</mu1>
    <mu2>0.2</mu2>
    <selfCollide>1</selfCollide>
  </gazebo>
  <gazebo reference="hexapod/leg_5/motor_0">
    <material>Gazebo/White</material>
    <mu1>0.2</mu1>
    <mu2>0.2</mu2>
    <selfCollide>1</selfCollide>
  </gazebo>
  <gazebo reference="hexapod/leg_5/motor_1">
    <material>Gazebo/White</material>
    <mu1>0.2</mu1>
    <mu2>0.2</mu2>
    <selfCollide>1</selfCollide>
  </gazebo>
  <gazebo reference="hexapod/leg_5/motor_2">
    <material>Gazebo/White</material>
    <mu1>0.2</mu1>
    <mu2>0.2</mu2>
    <selfCollide>1</selfCollide>
  </gazebo>
  <transmission name="hexapod/leg_0/tran_0">
    <robotNamespace>/hexapod</robotNamespace>
    <type>transmission_interface/SimpleTransmission</type>
    <joint name="hexapod/leg_0/joint_0">
      <hardwareInterface>hardware_interface/PositionJointInterface</hardwareInterface>
    </joint>
    <actuator name="hexapod/leg_0/motor_0">
      <hardwareInterface>hardware_interface/PositionJointInterface</hardwareInterface>
      <mechanicalReduction>1</mechanicalReduction>
    </actuator>
  </transmission>
  <transmission name="hexapod/leg_0/tran_1">
    <robotNamespace>/hexapod</robotNamespace>
    <type>transmission_interface/SimpleTransmission</type>
    <joint name="hexapod/leg_0/joint_1">
      <hardwareInterface>hardware_interface/PositionJointInterface</hardwareInterface>
    </joint>
    <actuator name="hexapod/leg_0/motor_1">
      <hardwareInterface>hardware_interface/PositionJointInterface</hardwareInterface>
      <mechanicalReduction>1</mechanicalReduction>
    </actuator>
  </transmission>
  <transmission name="hexapod/leg_0/tran_2">
    <robotNamespace>/hexapod</robotNamespace>
    <type>transmission_interface/SimpleTransmission</type>
    <joint name="hexapod/leg_0/joint_2">
      <hardwareInterface>hardware_interface/PositionJointInterface</hardwareInterface>
    </joint>
    <actuator name="hexapod/leg_0/motor_2">
      <hardwareInterface>hardware_interface/PositionJointInterface</hardwareInterface>
      <mechanicalReduction>1</mechanicalReduction>
    </actuator>
  </transmission>
  <transmission name="hexapod/leg_1/tran_0">
    <robotNamespace>/hexapod</robotNamespace>
    <type>transmission_interface/SimpleTransmission</type>
    <joint name="hexapod/leg_1/joint_0">
      <hardwareInterface>hardware_interface/PositionJointInterface</hardwareInterface>
    </joint>
    <actuator name="hexapod/leg_1/motor_0">
      <hardwareInterface>hardware_interface/PositionJointInterface</hardwareInterface>
      <mechanicalReduction>1</mechanicalReduction>
    </actuator>
  </transmission>
  <transmission name="hexapod/leg_1/tran_1">
    <robotNamespace>/hexapod</robotNamespace>
    <type>transmission_interface/SimpleTransmission</type>
    <joint name="hexapod/leg_1/joint_1">
      <hardwareInterface>hardware_interface/PositionJointInterface</hardwareInterface>
    </joint>
    <actuator name="hexapod/leg_1/motor_1">
      <hardwareInterface>hardware_interface/PositionJointInterface</hardwareInterface>
      <mechanicalReduction>1</mechanicalReduction>
    </actuator>
  </transmission>
  <transmission name="hexapod/leg_1/tran_2">
    <robotNamespace>/hexapod</robotNamespace>
    <type>transmission_interface/SimpleTransmission</type>
    <joint name="hexapod/leg_1/joint_2">
      <hardwareInterface>hardware_interface/PositionJointInterface</hardwareInterface>
    </joint>
    <actuator name="hexapod/leg_1/motor_2">
      <hardwareInterface>hardware_interface/PositionJointInterface</hardwareInterface>
      <mechanicalReduction>1</mechanicalReduction>
    </actuator>
  </transmission>
  <transmission name="hexapod/leg_2/tran_0">
    <robotNamespace>/hexapod</robotNamespace>
    <type>transmission_interface/SimpleTransmission</type>
    <joint name="hexapod/leg_2/joint_0">
      <hardwareInterface>hardware_interface/PositionJointInterface</hardwareInterface>
    </joint>
    <actuator name="hexapod/leg_2/motor_0">
      <hardwareInterface>hardware_interface/PositionJointInterface</hardwareInterface>
      <mechanicalReduction>1</mechanicalReduction>
    </actuator>
  </transmission>
  <transmission name="hexapod/leg_2/tran_1">
    <robotNamespace>/hexapod</robotNamespace>
    <type>transmission_interface/SimpleTransmission</type>
    <joint name="hexapod/leg_2/joint_1">
      <hardwareInterface>hardware_interface/PositionJointInterface</hardwareInterface>
    </joint>
    <actuator name="hexapod/leg_2/motor_1">
      <hardwareInterface>hardware_interface/PositionJointInterface</hardwareInterface>
      <mechanicalReduction>1</mechanicalReduction>
    </actuator>
  </transmission>
  <transmission name="hexapod/leg_2/tran_2">
    <robotNamespace>/hexapod</robotNamespace>
    <type>transmission_interface/SimpleTransmission</type>
    <joint name="hexapod/leg_2/joint_2">
      <hardwareInterface>hardware_interface/PositionJointInterface</hardwareInterface>
    </joint>
    <actuator name="hexapod/leg_2/motor_2">
      <hardwareInterface>hardware_interface/PositionJointInterface</hardwareInterface>
      <mechanicalReduction>1</mechanicalReduction>
    </actuator>
  </transmission>
  <transmission name="hexapod/leg_3/tran_0">
    <robotNamespace>/hexapod</robotNamespace>
    <type>transmission_interface/SimpleTransmission</type>
    <joint name="hexapod/leg_3/joint_0">
      <hardwareInterface>hardware_interface/PositionJointInterface</hardwareInterface>
    </joint>
    <actuator name="hexapod/leg_3/motor_0">
      <hardwareInterface>hardware_interface/PositionJointInterface</hardwareInterface>
      <mechanicalReduction>1</mechanicalReduction>
    </actuator>
  </transmission>
  <transmission name="hexapod/leg_3/tran_1">
    <robotNamespace>/hexapod</robotNamespace>
    <type>transmission_interface/SimpleTransmission</type>
    <joint name="hexapod/leg_3/joint_1">
      <hardwareInterface>hardware_interface/PositionJointInterface</hardwareInterface>
    </joint>
    <actuator name="hexapod/leg_3/motor_1">
      <hardwareInterface>hardware_interface/PositionJointInterface</hardwareInterface>
      <mechanicalReduction>1</mechanicalReduction>
    </actuator>
  </transmission>
  <transmission name="hexapod/leg_3/tran_2">
    <robotNamespace>/hexapod</robotNamespace>
    <type>transmission_interface/SimpleTransmission</type>
    <joint name="hexapod/leg_3/joint_2">
      <hardwareInterface>hardware_interface/PositionJointInterface</hardwareInterface>
    </joint>
    <actuator name="hexapod/leg_3/motor_2">
      <hardwareInterface>hardware_interface/PositionJointInterface</hardwareInterface>
      <mechanicalReduction>1</mechanicalReduction>
    </actuator>
  </transmission>
  <transmission name="hexapod/leg_4/tran_0">
    <robotNamespace>/hexapod</robotNamespace>
    <type>transmission_interface/SimpleTransmission</type>
    <joint name="hexapod/leg_4/joint_0">
      <hardwareInterface>hardware_interface/PositionJointInterface</hardwareInterface>
    </joint>
    <actuator name="hexapod/leg_4/motor_0">
      <hardwareInterface>hardware_interface/PositionJointInterface</hardwareInterface>
      <mechanicalReduction>1</mechanicalReduction>
    </actuator>
  </transmission>
  <transmission name="hexapod/leg_4/tran_1">
    <robotNamespace>/hexapod</robotNamespace>
    <type>transmission_interface/SimpleTransmission</type>
    <joint name="hexapod/leg_4/joint_1">
      <hardwareInterface>hardware_interface/PositionJointInterface</hardwareInterface>
    </joint>
    <actuator name="hexapod/leg_4/motor_1">
      <hardwareInterface>hardware_interface/PositionJointInterface</hardwareInterface>
      <mechanicalReduction>1</mechanicalReduction>
    </actuator>
  </transmission>
  <transmission name="hexapod/leg_4/tran_2">
    <robotNamespace>/hexapod</robotNamespace>
    <type>transmission_interface/SimpleTransmission</type>
    <joint name="hexapod/leg_4/joint_2">
      <hardwareInterface>hardware_interface/PositionJointInterface</hardwareInterface>
    </joint>
    <actuator name="hexapod/leg_4/motor_2">
      <hardwareInterface>hardware_interface/PositionJointInterface</hardwareInterface>
      <mechanicalReduction>1</mechanicalReduction>
    </actuator>
  </transmission>
  <transmission name="hexapod/leg_5/tran_0">
    <robotNamespace>/hexapod</robotNamespace>
    <type>transmission_interface/SimpleTransmission</type>
    <joint name="hexapod/leg_5/joint_0">
      <hardwareInterface>hardware_interface/PositionJointInterface</hardwareInterface>
    </joint>
    <actuator name="hexapod/leg_5/motor_0">
      <hardwareInterface>hardware_interface/PositionJointInterface</hardwareInterface>
      <mechanicalReduction>1</mechanicalReduction>
    </actuator>
  </transmission>
  <transmission name="hexapod/leg_5/tran_1">
    <robotNamespace>/hexapod</robotNamespace>
    <type>transmission_interface/SimpleTransmission</type>
    <joint name="hexapod/leg_5/joint_1">
      <hardwareInterface>hardware_interface/PositionJointInterface</hardwareInterface>
    </joint>
    <actuator name="hexapod/leg_5/motor_1">
      <hardwareInterface>hardware_interface/PositionJointInterface</hardwareInterface>
      <mechanicalReduction>1</mechanicalReduction>
    </actuator>
  </transmission>
  <transmission name="hexapod/leg_5/tran_2">
    <robotNamespace>/hexapod</robotNamespace>
    <type>transmission_interface/SimpleTransmission</type>
    <joint name="hexapod/leg_5/joint_2">
      <hardwareInterface>hardware_interface/PositionJointInterface</hardwareInterface>
    </joint>
    <actuator name="hexapod/leg_5/motor_2">
      <hardwareInterface>hardware_interface/PositionJointInterface</hardwareInterface>
      <mechanicalReduction>1</mechanicalReduction>
    </actuator>
  </transmission>
  <gazebo>
    <plugin filename="libgazebo_ros_control.so" name="gazebo_ros_control">
      <robotNamespace>/hexapod</robotNamespace>
    </plugin>
  </gazebo>
</robot>

